[2025-04-09T15:34:36.785+0000] {local_task_job_runner.py:123} INFO - ::group::Pre task execution logs
[2025-04-09T15:34:36.798+0000] {taskinstance.py:2614} INFO - Dependencies all met for dep_context=non-requeueable deps ti=<TaskInstance: weather_dag.is_weather_api_ready manual__2025-04-09T15:16:47.149330+00:00 [queued]>
[2025-04-09T15:34:36.808+0000] {taskinstance.py:2614} INFO - Dependencies all met for dep_context=requeueable deps ti=<TaskInstance: weather_dag.is_weather_api_ready manual__2025-04-09T15:16:47.149330+00:00 [queued]>
[2025-04-09T15:34:36.808+0000] {taskinstance.py:2867} INFO - Starting attempt 3 of 3
[2025-04-09T15:34:36.832+0000] {taskinstance.py:2890} INFO - Executing <Task(HttpSensor): is_weather_api_ready> on 2025-04-09 15:16:47.149330+00:00
[2025-04-09T15:34:36.841+0000] {standard_task_runner.py:72} INFO - Started process 29352 to run task
[2025-04-09T15:34:36.846+0000] {standard_task_runner.py:104} INFO - Running: ['airflow', 'tasks', 'run', 'weather_dag', 'is_weather_api_ready', 'manual__2025-04-09T15:16:47.149330+00:00', '--job-id', '56', '--raw', '--subdir', 'DAGS_FOLDER/weather_dag.py', '--cfg-path', '/tmp/tmpavgad4hg']
[2025-04-09T15:34:36.847+0000] {standard_task_runner.py:105} INFO - Job 56: Subtask is_weather_api_ready
[2025-04-09T15:34:36.891+0000] {task_command.py:467} INFO - Running <TaskInstance: weather_dag.is_weather_api_ready manual__2025-04-09T15:16:47.149330+00:00 [running]> on host ip-172-31-10-226.eu-north-1.compute.internal
[2025-04-09T15:34:36.974+0000] {taskinstance.py:3134} INFO - Exporting env vars: AIRFLOW_CTX_DAG_EMAIL='myemail@domain.com' AIRFLOW_CTX_DAG_OWNER='airflow' AIRFLOW_CTX_DAG_ID='weather_dag' AIRFLOW_CTX_TASK_ID='is_weather_api_ready' AIRFLOW_CTX_EXECUTION_DATE='2025-04-09T15:16:47.149330+00:00' AIRFLOW_CTX_TRY_NUMBER='3' AIRFLOW_CTX_DAG_RUN_ID='manual__2025-04-09T15:16:47.149330+00:00'
[2025-04-09T15:34:36.975+0000] {logging_mixin.py:190} INFO - Task instance is in running state
[2025-04-09T15:34:36.976+0000] {logging_mixin.py:190} INFO -  Previous state of the Task instance: queued
[2025-04-09T15:34:36.976+0000] {logging_mixin.py:190} INFO - Current task name:is_weather_api_ready state:running start_date:2025-04-09 15:34:36.799012+00:00
[2025-04-09T15:34:36.976+0000] {logging_mixin.py:190} INFO - Dag name:weather_dag and current dag run status:running
[2025-04-09T15:34:36.976+0000] {taskinstance.py:732} INFO - ::endgroup::
[2025-04-09T15:34:36.977+0000] {baseoperator.py:423} WARNING - HttpSensor.execute cannot be called outside TaskInstance!
[2025-04-09T15:34:36.978+0000] {http.py:145} INFO - Poking: /data/S2.5/weather?q=Portland&APPID=4d13f07efe491003cd53c704f189b00f
[2025-04-09T15:34:36.984+0000] {base.py:84} INFO - Retrieving connection 'weathermap_api'
[2025-04-09T15:34:37.088+0000] {http.py:278} ERROR - HTTP error: Not Found
[2025-04-09T15:34:37.089+0000] {http.py:279} ERROR - {"cod":"404","message":"Internal error"}
[2025-04-09T15:35:37.090+0000] {http.py:145} INFO - Poking: /data/S2.5/weather?q=Portland&APPID=4d13f07efe491003cd53c704f189b00f
[2025-04-09T15:35:37.094+0000] {base.py:84} INFO - Retrieving connection 'weathermap_api'
[2025-04-09T15:35:37.198+0000] {http.py:278} ERROR - HTTP error: Not Found
[2025-04-09T15:35:37.198+0000] {http.py:279} ERROR - {"cod":"404","message":"Internal error"}
[2025-04-09T15:36:37.199+0000] {http.py:145} INFO - Poking: /data/S2.5/weather?q=Portland&APPID=4d13f07efe491003cd53c704f189b00f
[2025-04-09T15:36:37.203+0000] {base.py:84} INFO - Retrieving connection 'weathermap_api'
[2025-04-09T15:36:37.288+0000] {http.py:278} ERROR - HTTP error: Not Found
[2025-04-09T15:36:37.288+0000] {http.py:279} ERROR - {"cod":"404","message":"Internal error"}
[2025-04-09T15:37:37.289+0000] {http.py:145} INFO - Poking: /data/S2.5/weather?q=Portland&APPID=4d13f07efe491003cd53c704f189b00f
[2025-04-09T15:37:37.292+0000] {base.py:84} INFO - Retrieving connection 'weathermap_api'
[2025-04-09T15:37:37.379+0000] {http.py:278} ERROR - HTTP error: Not Found
[2025-04-09T15:37:37.379+0000] {http.py:279} ERROR - {"cod":"404","message":"Internal error"}
[2025-04-09T15:38:37.380+0000] {http.py:145} INFO - Poking: /data/S2.5/weather?q=Portland&APPID=4d13f07efe491003cd53c704f189b00f
[2025-04-09T15:38:37.383+0000] {base.py:84} INFO - Retrieving connection 'weathermap_api'
[2025-04-09T15:38:37.467+0000] {http.py:278} ERROR - HTTP error: Not Found
[2025-04-09T15:38:37.467+0000] {http.py:279} ERROR - {"cod":"404","message":"Internal error"}
[2025-04-09T15:39:37.468+0000] {http.py:145} INFO - Poking: /data/S2.5/weather?q=Portland&APPID=4d13f07efe491003cd53c704f189b00f
[2025-04-09T15:39:37.471+0000] {base.py:84} INFO - Retrieving connection 'weathermap_api'
[2025-04-09T15:39:37.559+0000] {http.py:278} ERROR - HTTP error: Not Found
[2025-04-09T15:39:37.559+0000] {http.py:279} ERROR - {"cod":"404","message":"Internal error"}
[2025-04-09T15:40:37.560+0000] {http.py:145} INFO - Poking: /data/S2.5/weather?q=Portland&APPID=4d13f07efe491003cd53c704f189b00f
[2025-04-09T15:40:37.563+0000] {base.py:84} INFO - Retrieving connection 'weathermap_api'
[2025-04-09T15:40:37.641+0000] {http.py:278} ERROR - HTTP error: Not Found
[2025-04-09T15:40:37.642+0000] {http.py:279} ERROR - {"cod":"404","message":"Internal error"}
[2025-04-09T15:41:37.642+0000] {http.py:145} INFO - Poking: /data/S2.5/weather?q=Portland&APPID=4d13f07efe491003cd53c704f189b00f
[2025-04-09T15:41:37.646+0000] {base.py:84} INFO - Retrieving connection 'weathermap_api'
[2025-04-09T15:41:37.729+0000] {http.py:278} ERROR - HTTP error: Not Found
[2025-04-09T15:41:37.729+0000] {http.py:279} ERROR - {"cod":"404","message":"Internal error"}
[2025-04-09T15:42:37.730+0000] {http.py:145} INFO - Poking: /data/S2.5/weather?q=Portland&APPID=4d13f07efe491003cd53c704f189b00f
[2025-04-09T15:42:37.734+0000] {base.py:84} INFO - Retrieving connection 'weathermap_api'
[2025-04-09T15:42:37.817+0000] {http.py:278} ERROR - HTTP error: Not Found
[2025-04-09T15:42:37.817+0000] {http.py:279} ERROR - {"cod":"404","message":"Internal error"}
[2025-04-09T15:43:37.818+0000] {http.py:145} INFO - Poking: /data/S2.5/weather?q=Portland&APPID=4d13f07efe491003cd53c704f189b00f
[2025-04-09T15:43:37.821+0000] {base.py:84} INFO - Retrieving connection 'weathermap_api'
[2025-04-09T15:43:37.919+0000] {http.py:278} ERROR - HTTP error: Not Found
[2025-04-09T15:43:37.919+0000] {http.py:279} ERROR - {"cod":"404","message":"Internal error"}
[2025-04-09T15:44:37.920+0000] {http.py:145} INFO - Poking: /data/S2.5/weather?q=Portland&APPID=4d13f07efe491003cd53c704f189b00f
[2025-04-09T15:44:37.924+0000] {base.py:84} INFO - Retrieving connection 'weathermap_api'
[2025-04-09T15:44:38.022+0000] {http.py:278} ERROR - HTTP error: Not Found
[2025-04-09T15:44:38.022+0000] {http.py:279} ERROR - {"cod":"404","message":"Internal error"}
[2025-04-09T15:45:38.023+0000] {http.py:145} INFO - Poking: /data/S2.5/weather?q=Portland&APPID=4d13f07efe491003cd53c704f189b00f
[2025-04-09T15:45:38.029+0000] {base.py:84} INFO - Retrieving connection 'weathermap_api'
[2025-04-09T15:45:38.129+0000] {http.py:278} ERROR - HTTP error: Not Found
[2025-04-09T15:45:38.129+0000] {http.py:279} ERROR - {"cod":"404","message":"Internal error"}
[2025-04-09T15:46:38.130+0000] {http.py:145} INFO - Poking: /data/S2.5/weather?q=Portland&APPID=4d13f07efe491003cd53c704f189b00f
[2025-04-09T15:46:38.135+0000] {base.py:84} INFO - Retrieving connection 'weathermap_api'
[2025-04-09T15:46:38.239+0000] {http.py:278} ERROR - HTTP error: Not Found
[2025-04-09T15:46:38.242+0000] {http.py:279} ERROR - {"cod":"404","message":"Internal error"}
[2025-04-09T15:47:29.362+0000] {local_task_job_runner.py:346} WARNING - State of this instance has been externally set to success. Terminating instance.
[2025-04-09T15:47:29.363+0000] {local_task_job_runner.py:245} INFO - ::endgroup::
[2025-04-09T15:47:29.369+0000] {process_utils.py:132} INFO - Sending 15 to group 29352. PIDs of all processes in the group: [29352]
[2025-04-09T15:47:29.369+0000] {process_utils.py:87} INFO - Sending the signal 15 to group 29352
[2025-04-09T15:47:29.370+0000] {taskinstance.py:3094} ERROR - Received SIGTERM. Terminating subprocesses.
[2025-04-09T15:47:29.373+0000] {taskinstance.py:3095} ERROR - Stacktrace: 
  File "/home/ubuntu/airflow_venv/bin/airflow", line 8, in <module>
    sys.exit(main())
  File "/home/ubuntu/airflow_venv/lib/python3.12/site-packages/airflow/__main__.py", line 62, in main
    args.func(args)
  File "/home/ubuntu/airflow_venv/lib/python3.12/site-packages/airflow/cli/cli_config.py", line 49, in command
    return func(*args, **kwargs)
  File "/home/ubuntu/airflow_venv/lib/python3.12/site-packages/airflow/utils/cli.py", line 116, in wrapper
    return f(*args, **kwargs)
  File "/home/ubuntu/airflow_venv/lib/python3.12/site-packages/airflow/cli/commands/task_command.py", line 483, in task_run
    task_return_code = _run_task_by_selected_method(args, _dag, ti)
  File "/home/ubuntu/airflow_venv/lib/python3.12/site-packages/airflow/cli/commands/task_command.py", line 254, in _run_task_by_selected_method
    return _run_task_by_local_task_job(args, ti)
  File "/home/ubuntu/airflow_venv/lib/python3.12/site-packages/airflow/cli/commands/task_command.py", line 322, in _run_task_by_local_task_job
    ret = run_job(job=job_runner.job, execute_callable=job_runner._execute)
  File "/home/ubuntu/airflow_venv/lib/python3.12/site-packages/airflow/utils/session.py", line 97, in wrapper
    return func(*args, session=session, **kwargs)
  File "/home/ubuntu/airflow_venv/lib/python3.12/site-packages/airflow/jobs/job.py", line 421, in run_job
    return execute_job(job, execute_callable=execute_callable)
  File "/home/ubuntu/airflow_venv/lib/python3.12/site-packages/airflow/jobs/job.py", line 450, in execute_job
    ret = execute_callable()
  File "/home/ubuntu/airflow_venv/lib/python3.12/site-packages/airflow/jobs/local_task_job_runner.py", line 171, in _execute
    self.task_runner.start()
  File "/home/ubuntu/airflow_venv/lib/python3.12/site-packages/airflow/task/task_runner/standard_task_runner.py", line 55, in start
    self.process = self._start_by_fork()
  File "/home/ubuntu/airflow_venv/lib/python3.12/site-packages/airflow/task/task_runner/standard_task_runner.py", line 117, in _start_by_fork
    ret = args.func(args, dag=self.dag)
  File "/home/ubuntu/airflow_venv/lib/python3.12/site-packages/airflow/cli/cli_config.py", line 49, in command
    return func(*args, **kwargs)
  File "/home/ubuntu/airflow_venv/lib/python3.12/site-packages/airflow/utils/cli.py", line 116, in wrapper
    return f(*args, **kwargs)
  File "/home/ubuntu/airflow_venv/lib/python3.12/site-packages/airflow/cli/commands/task_command.py", line 483, in task_run
    task_return_code = _run_task_by_selected_method(args, _dag, ti)
  File "/home/ubuntu/airflow_venv/lib/python3.12/site-packages/airflow/cli/commands/task_command.py", line 256, in _run_task_by_selected_method
    return _run_raw_task(args, ti)
  File "/home/ubuntu/airflow_venv/lib/python3.12/site-packages/airflow/cli/commands/task_command.py", line 341, in _run_raw_task
    return ti._run_raw_task(
  File "/home/ubuntu/airflow_venv/lib/python3.12/site-packages/airflow/utils/session.py", line 97, in wrapper
    return func(*args, session=session, **kwargs)
  File "/home/ubuntu/airflow_venv/lib/python3.12/site-packages/airflow/models/taskinstance.py", line 3006, in _run_raw_task
    return _run_raw_task(
  File "/home/ubuntu/airflow_venv/lib/python3.12/site-packages/airflow/models/taskinstance.py", line 274, in _run_raw_task
    TaskInstance._execute_task_with_callbacks(
  File "/home/ubuntu/airflow_venv/lib/python3.12/site-packages/airflow/models/taskinstance.py", line 3161, in _execute_task_with_callbacks
    result = self._execute_task(context, task_orig)
  File "/home/ubuntu/airflow_venv/lib/python3.12/site-packages/airflow/models/taskinstance.py", line 3185, in _execute_task
    return _execute_task(self, context, task_orig)
  File "/home/ubuntu/airflow_venv/lib/python3.12/site-packages/airflow/models/taskinstance.py", line 768, in _execute_task
    result = _execute_callable(context=context, **execute_callable_kwargs)
  File "/home/ubuntu/airflow_venv/lib/python3.12/site-packages/airflow/models/taskinstance.py", line 734, in _execute_callable
    return ExecutionCallableRunner(
  File "/home/ubuntu/airflow_venv/lib/python3.12/site-packages/airflow/utils/operator_helpers.py", line 252, in run
    return self.func(*args, **kwargs)
  File "/home/ubuntu/airflow_venv/lib/python3.12/site-packages/airflow/models/baseoperator.py", line 424, in wrapper
    return func(self, *args, **kwargs)
  File "/home/ubuntu/airflow_venv/lib/python3.12/site-packages/airflow/providers/http/sensors/http.py", line 169, in execute
    return super().execute(context=context)
  File "/home/ubuntu/airflow_venv/lib/python3.12/site-packages/airflow/models/baseoperator.py", line 424, in wrapper
    return func(self, *args, **kwargs)
  File "/home/ubuntu/airflow_venv/lib/python3.12/site-packages/airflow/sensors/base.py", line 337, in execute
    time.sleep(self._get_next_poke_interval(started_at, run_duration, poke_count))
  File "/home/ubuntu/airflow_venv/lib/python3.12/site-packages/airflow/models/taskinstance.py", line 3095, in signal_handler
    self.log.error("Stacktrace: \n%s", "".join(traceback.format_stack()))

[2025-04-09T15:47:29.403+0000] {taskinstance.py:341} INFO - ::group::Post task execution logs
[2025-04-09T15:47:29.423+0000] {process_utils.py:80} INFO - Process psutil.Process(pid=29352, status='terminated', exitcode=0, started='15:34:36') (29352) terminated with exit code 0
