[2025-04-09T12:36:24.266+0000] {local_task_job_runner.py:123} INFO - ::group::Pre task execution logs
[2025-04-09T12:36:24.288+0000] {taskinstance.py:2614} INFO - Dependencies all met for dep_context=non-requeueable deps ti=<TaskInstance: weather_dag.is_weather_api_ready scheduled__2025-04-08T00:00:00+00:00 [queued]>
[2025-04-09T12:36:24.294+0000] {taskinstance.py:2614} INFO - Dependencies all met for dep_context=requeueable deps ti=<TaskInstance: weather_dag.is_weather_api_ready scheduled__2025-04-08T00:00:00+00:00 [queued]>
[2025-04-09T12:36:24.295+0000] {taskinstance.py:2867} INFO - Starting attempt 1 of 3
[2025-04-09T12:36:24.311+0000] {taskinstance.py:2890} INFO - Executing <Task(HttpSensor): is_weather_api_ready> on 2025-04-08 00:00:00+00:00
[2025-04-09T12:36:24.317+0000] {standard_task_runner.py:72} INFO - Started process 21868 to run task
[2025-04-09T12:36:24.322+0000] {standard_task_runner.py:104} INFO - Running: ['airflow', 'tasks', 'run', 'weather_dag', 'is_weather_api_ready', 'scheduled__2025-04-08T00:00:00+00:00', '--job-id', '11', '--raw', '--subdir', 'DAGS_FOLDER/weather_dag.py', '--cfg-path', '/tmp/tmp0xrbdzto']
[2025-04-09T12:36:24.323+0000] {standard_task_runner.py:105} INFO - Job 11: Subtask is_weather_api_ready
[2025-04-09T12:36:24.372+0000] {task_command.py:467} INFO - Running <TaskInstance: weather_dag.is_weather_api_ready scheduled__2025-04-08T00:00:00+00:00 [running]> on host ip-172-31-10-226.eu-north-1.compute.internal
[2025-04-09T12:36:24.677+0000] {taskinstance.py:3134} INFO - Exporting env vars: AIRFLOW_CTX_DAG_EMAIL='myemail@domain.com' AIRFLOW_CTX_DAG_OWNER='airflow' AIRFLOW_CTX_DAG_ID='weather_dag' AIRFLOW_CTX_TASK_ID='is_weather_api_ready' AIRFLOW_CTX_EXECUTION_DATE='2025-04-08T00:00:00+00:00' AIRFLOW_CTX_TRY_NUMBER='1' AIRFLOW_CTX_DAG_RUN_ID='scheduled__2025-04-08T00:00:00+00:00'
[2025-04-09T12:36:24.678+0000] {logging_mixin.py:190} INFO - Task instance is in running state
[2025-04-09T12:36:24.678+0000] {logging_mixin.py:190} INFO -  Previous state of the Task instance: queued
[2025-04-09T12:36:24.679+0000] {logging_mixin.py:190} INFO - Current task name:is_weather_api_ready state:running start_date:2025-04-09 12:36:24.289141+00:00
[2025-04-09T12:36:24.679+0000] {logging_mixin.py:190} INFO - Dag name:weather_dag and current dag run status:running
[2025-04-09T12:36:24.679+0000] {taskinstance.py:732} INFO - ::endgroup::
[2025-04-09T12:36:24.679+0000] {baseoperator.py:423} WARNING - HttpSensor.execute cannot be called outside TaskInstance!
[2025-04-09T12:36:24.680+0000] {http.py:145} INFO - Poking: /data/S2.5/weather?q=Portland&APPID=4d13f07efe491003cd53c704f189b00f
[2025-04-09T12:36:24.684+0000] {base.py:84} INFO - Retrieving connection 'weathermap_api'
[2025-04-09T12:36:24.771+0000] {http.py:278} ERROR - HTTP error: Not Found
[2025-04-09T12:36:24.771+0000] {http.py:279} ERROR - {"cod":"404","message":"Internal error"}
[2025-04-09T12:37:24.772+0000] {http.py:145} INFO - Poking: /data/S2.5/weather?q=Portland&APPID=4d13f07efe491003cd53c704f189b00f
[2025-04-09T12:37:24.778+0000] {base.py:84} INFO - Retrieving connection 'weathermap_api'
[2025-04-09T12:37:24.868+0000] {http.py:278} ERROR - HTTP error: Not Found
[2025-04-09T12:37:24.868+0000] {http.py:279} ERROR - {"cod":"404","message":"Internal error"}
[2025-04-09T12:38:24.869+0000] {http.py:145} INFO - Poking: /data/S2.5/weather?q=Portland&APPID=4d13f07efe491003cd53c704f189b00f
[2025-04-09T12:38:24.873+0000] {base.py:84} INFO - Retrieving connection 'weathermap_api'
[2025-04-09T12:38:24.980+0000] {http.py:278} ERROR - HTTP error: Not Found
[2025-04-09T12:38:24.981+0000] {http.py:279} ERROR - {"cod":"404","message":"Internal error"}
[2025-04-09T12:39:24.981+0000] {http.py:145} INFO - Poking: /data/S2.5/weather?q=Portland&APPID=4d13f07efe491003cd53c704f189b00f
[2025-04-09T12:39:24.985+0000] {base.py:84} INFO - Retrieving connection 'weathermap_api'
[2025-04-09T12:39:25.088+0000] {http.py:278} ERROR - HTTP error: Not Found
[2025-04-09T12:39:25.088+0000] {http.py:279} ERROR - {"cod":"404","message":"Internal error"}
[2025-04-09T12:40:25.089+0000] {http.py:145} INFO - Poking: /data/S2.5/weather?q=Portland&APPID=4d13f07efe491003cd53c704f189b00f
[2025-04-09T12:40:25.093+0000] {base.py:84} INFO - Retrieving connection 'weathermap_api'
[2025-04-09T12:40:25.184+0000] {http.py:278} ERROR - HTTP error: Not Found
[2025-04-09T12:40:25.184+0000] {http.py:279} ERROR - {"cod":"404","message":"Internal error"}
[2025-04-09T12:41:25.185+0000] {http.py:145} INFO - Poking: /data/S2.5/weather?q=Portland&APPID=4d13f07efe491003cd53c704f189b00f
[2025-04-09T12:41:25.189+0000] {base.py:84} INFO - Retrieving connection 'weathermap_api'
[2025-04-09T12:41:25.273+0000] {http.py:278} ERROR - HTTP error: Not Found
[2025-04-09T12:41:25.274+0000] {http.py:279} ERROR - {"cod":"404","message":"Internal error"}
[2025-04-09T12:42:25.275+0000] {http.py:145} INFO - Poking: /data/S2.5/weather?q=Portland&APPID=4d13f07efe491003cd53c704f189b00f
[2025-04-09T12:42:25.278+0000] {base.py:84} INFO - Retrieving connection 'weathermap_api'
[2025-04-09T12:42:25.372+0000] {http.py:278} ERROR - HTTP error: Not Found
[2025-04-09T12:42:25.374+0000] {http.py:279} ERROR - {"cod":"404","message":"Internal error"}
[2025-04-09T12:43:25.375+0000] {http.py:145} INFO - Poking: /data/S2.5/weather?q=Portland&APPID=4d13f07efe491003cd53c704f189b00f
[2025-04-09T12:43:25.377+0000] {base.py:84} INFO - Retrieving connection 'weathermap_api'
[2025-04-09T12:43:25.461+0000] {http.py:278} ERROR - HTTP error: Not Found
[2025-04-09T12:43:25.461+0000] {http.py:279} ERROR - {"cod":"404","message":"Internal error"}
[2025-04-09T12:44:25.462+0000] {http.py:145} INFO - Poking: /data/S2.5/weather?q=Portland&APPID=4d13f07efe491003cd53c704f189b00f
[2025-04-09T12:44:25.465+0000] {base.py:84} INFO - Retrieving connection 'weathermap_api'
[2025-04-09T12:44:25.550+0000] {http.py:278} ERROR - HTTP error: Not Found
[2025-04-09T12:44:25.550+0000] {http.py:279} ERROR - {"cod":"404","message":"Internal error"}
[2025-04-09T12:45:25.551+0000] {http.py:145} INFO - Poking: /data/S2.5/weather?q=Portland&APPID=4d13f07efe491003cd53c704f189b00f
[2025-04-09T12:45:25.559+0000] {base.py:84} INFO - Retrieving connection 'weathermap_api'
[2025-04-09T12:45:25.648+0000] {http.py:278} ERROR - HTTP error: Not Found
[2025-04-09T12:45:25.649+0000] {http.py:279} ERROR - {"cod":"404","message":"Internal error"}
[2025-04-09T12:46:25.649+0000] {http.py:145} INFO - Poking: /data/S2.5/weather?q=Portland&APPID=4d13f07efe491003cd53c704f189b00f
[2025-04-09T12:46:25.656+0000] {base.py:84} INFO - Retrieving connection 'weathermap_api'
[2025-04-09T12:46:25.748+0000] {http.py:278} ERROR - HTTP error: Not Found
[2025-04-09T12:46:25.748+0000] {http.py:279} ERROR - {"cod":"404","message":"Internal error"}
[2025-04-09T12:47:25.749+0000] {http.py:145} INFO - Poking: /data/S2.5/weather?q=Portland&APPID=4d13f07efe491003cd53c704f189b00f
[2025-04-09T12:47:25.752+0000] {base.py:84} INFO - Retrieving connection 'weathermap_api'
[2025-04-09T12:47:25.855+0000] {http.py:278} ERROR - HTTP error: Not Found
[2025-04-09T12:47:25.855+0000] {http.py:279} ERROR - {"cod":"404","message":"Internal error"}
[2025-04-09T12:48:25.856+0000] {http.py:145} INFO - Poking: /data/S2.5/weather?q=Portland&APPID=4d13f07efe491003cd53c704f189b00f
[2025-04-09T12:48:25.859+0000] {base.py:84} INFO - Retrieving connection 'weathermap_api'
[2025-04-09T12:48:25.943+0000] {http.py:278} ERROR - HTTP error: Not Found
[2025-04-09T12:48:25.944+0000] {http.py:279} ERROR - {"cod":"404","message":"Internal error"}
[2025-04-09T12:49:25.944+0000] {http.py:145} INFO - Poking: /data/S2.5/weather?q=Portland&APPID=4d13f07efe491003cd53c704f189b00f
[2025-04-09T12:49:25.948+0000] {base.py:84} INFO - Retrieving connection 'weathermap_api'
[2025-04-09T12:49:26.037+0000] {http.py:278} ERROR - HTTP error: Not Found
[2025-04-09T12:49:26.037+0000] {http.py:279} ERROR - {"cod":"404","message":"Internal error"}
[2025-04-09T12:50:26.038+0000] {http.py:145} INFO - Poking: /data/S2.5/weather?q=Portland&APPID=4d13f07efe491003cd53c704f189b00f
[2025-04-09T12:50:26.043+0000] {base.py:84} INFO - Retrieving connection 'weathermap_api'
[2025-04-09T12:50:26.130+0000] {http.py:278} ERROR - HTTP error: Not Found
[2025-04-09T12:50:26.130+0000] {http.py:279} ERROR - {"cod":"404","message":"Internal error"}
[2025-04-09T12:51:26.132+0000] {http.py:145} INFO - Poking: /data/S2.5/weather?q=Portland&APPID=4d13f07efe491003cd53c704f189b00f
[2025-04-09T12:51:26.137+0000] {base.py:84} INFO - Retrieving connection 'weathermap_api'
[2025-04-09T12:51:26.222+0000] {http.py:278} ERROR - HTTP error: Not Found
[2025-04-09T12:51:26.222+0000] {http.py:279} ERROR - {"cod":"404","message":"Internal error"}
[2025-04-09T12:52:26.223+0000] {http.py:145} INFO - Poking: /data/S2.5/weather?q=Portland&APPID=4d13f07efe491003cd53c704f189b00f
[2025-04-09T12:52:26.227+0000] {base.py:84} INFO - Retrieving connection 'weathermap_api'
[2025-04-09T12:52:26.319+0000] {http.py:278} ERROR - HTTP error: Not Found
[2025-04-09T12:52:26.320+0000] {http.py:279} ERROR - {"cod":"404","message":"Internal error"}
[2025-04-09T12:53:26.320+0000] {http.py:145} INFO - Poking: /data/S2.5/weather?q=Portland&APPID=4d13f07efe491003cd53c704f189b00f
[2025-04-09T12:53:26.325+0000] {base.py:84} INFO - Retrieving connection 'weathermap_api'
[2025-04-09T12:53:26.419+0000] {http.py:278} ERROR - HTTP error: Not Found
[2025-04-09T12:53:26.419+0000] {http.py:279} ERROR - {"cod":"404","message":"Internal error"}
[2025-04-09T12:54:26.420+0000] {http.py:145} INFO - Poking: /data/S2.5/weather?q=Portland&APPID=4d13f07efe491003cd53c704f189b00f
[2025-04-09T12:54:26.425+0000] {base.py:84} INFO - Retrieving connection 'weathermap_api'
[2025-04-09T12:54:26.517+0000] {http.py:278} ERROR - HTTP error: Not Found
[2025-04-09T12:54:26.517+0000] {http.py:279} ERROR - {"cod":"404","message":"Internal error"}
[2025-04-09T12:55:26.518+0000] {http.py:145} INFO - Poking: /data/S2.5/weather?q=Portland&APPID=4d13f07efe491003cd53c704f189b00f
[2025-04-09T12:55:26.521+0000] {base.py:84} INFO - Retrieving connection 'weathermap_api'
[2025-04-09T12:55:26.630+0000] {http.py:278} ERROR - HTTP error: Not Found
[2025-04-09T12:55:26.631+0000] {http.py:279} ERROR - {"cod":"404","message":"Internal error"}
[2025-04-09T12:56:26.632+0000] {http.py:145} INFO - Poking: /data/S2.5/weather?q=Portland&APPID=4d13f07efe491003cd53c704f189b00f
[2025-04-09T12:56:26.644+0000] {base.py:84} INFO - Retrieving connection 'weathermap_api'
[2025-04-09T12:56:26.740+0000] {http.py:278} ERROR - HTTP error: Not Found
[2025-04-09T12:56:26.741+0000] {http.py:279} ERROR - {"cod":"404","message":"Internal error"}
[2025-04-09T12:57:26.741+0000] {http.py:145} INFO - Poking: /data/S2.5/weather?q=Portland&APPID=4d13f07efe491003cd53c704f189b00f
[2025-04-09T12:57:26.746+0000] {base.py:84} INFO - Retrieving connection 'weathermap_api'
[2025-04-09T12:57:26.841+0000] {http.py:278} ERROR - HTTP error: Not Found
[2025-04-09T12:57:26.842+0000] {http.py:279} ERROR - {"cod":"404","message":"Internal error"}
[2025-04-09T12:58:26.843+0000] {http.py:145} INFO - Poking: /data/S2.5/weather?q=Portland&APPID=4d13f07efe491003cd53c704f189b00f
[2025-04-09T12:58:26.846+0000] {base.py:84} INFO - Retrieving connection 'weathermap_api'
[2025-04-09T12:58:26.950+0000] {http.py:278} ERROR - HTTP error: Not Found
[2025-04-09T12:58:26.950+0000] {http.py:279} ERROR - {"cod":"404","message":"Internal error"}
[2025-04-09T12:59:26.951+0000] {http.py:145} INFO - Poking: /data/S2.5/weather?q=Portland&APPID=4d13f07efe491003cd53c704f189b00f
[2025-04-09T12:59:26.955+0000] {base.py:84} INFO - Retrieving connection 'weathermap_api'
[2025-04-09T12:59:27.054+0000] {http.py:278} ERROR - HTTP error: Not Found
[2025-04-09T12:59:27.055+0000] {http.py:279} ERROR - {"cod":"404","message":"Internal error"}
[2025-04-09T13:00:27.057+0000] {http.py:145} INFO - Poking: /data/S2.5/weather?q=Portland&APPID=4d13f07efe491003cd53c704f189b00f
[2025-04-09T13:00:27.062+0000] {base.py:84} INFO - Retrieving connection 'weathermap_api'
[2025-04-09T13:00:27.154+0000] {http.py:278} ERROR - HTTP error: Not Found
[2025-04-09T13:00:27.155+0000] {http.py:279} ERROR - {"cod":"404","message":"Internal error"}
[2025-04-09T13:01:27.155+0000] {http.py:145} INFO - Poking: /data/S2.5/weather?q=Portland&APPID=4d13f07efe491003cd53c704f189b00f
[2025-04-09T13:01:27.158+0000] {base.py:84} INFO - Retrieving connection 'weathermap_api'
[2025-04-09T13:01:27.252+0000] {http.py:278} ERROR - HTTP error: Not Found
[2025-04-09T13:01:27.252+0000] {http.py:279} ERROR - {"cod":"404","message":"Internal error"}
[2025-04-09T13:02:27.253+0000] {http.py:145} INFO - Poking: /data/S2.5/weather?q=Portland&APPID=4d13f07efe491003cd53c704f189b00f
[2025-04-09T13:02:27.256+0000] {base.py:84} INFO - Retrieving connection 'weathermap_api'
[2025-04-09T13:02:27.343+0000] {http.py:278} ERROR - HTTP error: Not Found
[2025-04-09T13:02:27.344+0000] {http.py:279} ERROR - {"cod":"404","message":"Internal error"}
[2025-04-09T13:03:27.345+0000] {http.py:145} INFO - Poking: /data/S2.5/weather?q=Portland&APPID=4d13f07efe491003cd53c704f189b00f
[2025-04-09T13:03:27.348+0000] {base.py:84} INFO - Retrieving connection 'weathermap_api'
[2025-04-09T13:03:27.438+0000] {http.py:278} ERROR - HTTP error: Not Found
[2025-04-09T13:03:27.438+0000] {http.py:279} ERROR - {"cod":"404","message":"Internal error"}
[2025-04-09T13:04:27.440+0000] {http.py:145} INFO - Poking: /data/S2.5/weather?q=Portland&APPID=4d13f07efe491003cd53c704f189b00f
[2025-04-09T13:04:27.443+0000] {base.py:84} INFO - Retrieving connection 'weathermap_api'
[2025-04-09T13:04:27.549+0000] {http.py:278} ERROR - HTTP error: Not Found
[2025-04-09T13:04:27.550+0000] {http.py:279} ERROR - {"cod":"404","message":"Internal error"}
[2025-04-09T13:05:27.551+0000] {http.py:145} INFO - Poking: /data/S2.5/weather?q=Portland&APPID=4d13f07efe491003cd53c704f189b00f
[2025-04-09T13:05:27.554+0000] {base.py:84} INFO - Retrieving connection 'weathermap_api'
[2025-04-09T13:05:27.637+0000] {http.py:278} ERROR - HTTP error: Not Found
[2025-04-09T13:05:27.637+0000] {http.py:279} ERROR - {"cod":"404","message":"Internal error"}
[2025-04-09T13:06:27.638+0000] {http.py:145} INFO - Poking: /data/S2.5/weather?q=Portland&APPID=4d13f07efe491003cd53c704f189b00f
[2025-04-09T13:06:27.642+0000] {base.py:84} INFO - Retrieving connection 'weathermap_api'
[2025-04-09T13:06:27.750+0000] {http.py:278} ERROR - HTTP error: Not Found
[2025-04-09T13:06:27.751+0000] {http.py:279} ERROR - {"cod":"404","message":"Internal error"}
[2025-04-09T13:07:27.752+0000] {http.py:145} INFO - Poking: /data/S2.5/weather?q=Portland&APPID=4d13f07efe491003cd53c704f189b00f
[2025-04-09T13:07:27.755+0000] {base.py:84} INFO - Retrieving connection 'weathermap_api'
[2025-04-09T13:07:27.864+0000] {http.py:278} ERROR - HTTP error: Not Found
[2025-04-09T13:07:27.864+0000] {http.py:279} ERROR - {"cod":"404","message":"Internal error"}
[2025-04-09T13:08:27.865+0000] {http.py:145} INFO - Poking: /data/S2.5/weather?q=Portland&APPID=4d13f07efe491003cd53c704f189b00f
[2025-04-09T13:08:27.870+0000] {base.py:84} INFO - Retrieving connection 'weathermap_api'
[2025-04-09T13:08:27.966+0000] {http.py:278} ERROR - HTTP error: Not Found
[2025-04-09T13:08:27.967+0000] {http.py:279} ERROR - {"cod":"404","message":"Internal error"}
[2025-04-09T13:09:27.967+0000] {http.py:145} INFO - Poking: /data/S2.5/weather?q=Portland&APPID=4d13f07efe491003cd53c704f189b00f
[2025-04-09T13:09:27.970+0000] {base.py:84} INFO - Retrieving connection 'weathermap_api'
[2025-04-09T13:09:28.069+0000] {http.py:278} ERROR - HTTP error: Not Found
[2025-04-09T13:09:28.069+0000] {http.py:279} ERROR - {"cod":"404","message":"Internal error"}
[2025-04-09T13:10:28.071+0000] {http.py:145} INFO - Poking: /data/S2.5/weather?q=Portland&APPID=4d13f07efe491003cd53c704f189b00f
[2025-04-09T13:10:28.074+0000] {base.py:84} INFO - Retrieving connection 'weathermap_api'
[2025-04-09T13:10:28.164+0000] {http.py:278} ERROR - HTTP error: Not Found
[2025-04-09T13:10:28.164+0000] {http.py:279} ERROR - {"cod":"404","message":"Internal error"}
[2025-04-09T13:10:38.319+0000] {local_task_job_runner.py:245} INFO - ::endgroup::
[2025-04-09T13:10:38.324+0000] {process_utils.py:132} INFO - Sending 15 to group 21868. PIDs of all processes in the group: [21868]
[2025-04-09T13:10:38.328+0000] {process_utils.py:87} INFO - Sending the signal 15 to group 21868
[2025-04-09T13:10:38.328+0000] {taskinstance.py:3094} ERROR - Received SIGTERM. Terminating subprocesses.
[2025-04-09T13:10:38.339+0000] {taskinstance.py:3095} ERROR - Stacktrace: 
  File "/home/ubuntu/airflow_venv/bin/airflow", line 8, in <module>
    sys.exit(main())
  File "/home/ubuntu/airflow_venv/lib/python3.12/site-packages/airflow/__main__.py", line 62, in main
    args.func(args)
  File "/home/ubuntu/airflow_venv/lib/python3.12/site-packages/airflow/cli/cli_config.py", line 49, in command
    return func(*args, **kwargs)
  File "/home/ubuntu/airflow_venv/lib/python3.12/site-packages/airflow/utils/cli.py", line 116, in wrapper
    return f(*args, **kwargs)
  File "/home/ubuntu/airflow_venv/lib/python3.12/site-packages/airflow/cli/commands/task_command.py", line 483, in task_run
    task_return_code = _run_task_by_selected_method(args, _dag, ti)
  File "/home/ubuntu/airflow_venv/lib/python3.12/site-packages/airflow/cli/commands/task_command.py", line 254, in _run_task_by_selected_method
    return _run_task_by_local_task_job(args, ti)
  File "/home/ubuntu/airflow_venv/lib/python3.12/site-packages/airflow/cli/commands/task_command.py", line 322, in _run_task_by_local_task_job
    ret = run_job(job=job_runner.job, execute_callable=job_runner._execute)
  File "/home/ubuntu/airflow_venv/lib/python3.12/site-packages/airflow/utils/session.py", line 97, in wrapper
    return func(*args, session=session, **kwargs)
  File "/home/ubuntu/airflow_venv/lib/python3.12/site-packages/airflow/jobs/job.py", line 421, in run_job
    return execute_job(job, execute_callable=execute_callable)
  File "/home/ubuntu/airflow_venv/lib/python3.12/site-packages/airflow/jobs/job.py", line 450, in execute_job
    ret = execute_callable()
  File "/home/ubuntu/airflow_venv/lib/python3.12/site-packages/airflow/jobs/local_task_job_runner.py", line 171, in _execute
    self.task_runner.start()
  File "/home/ubuntu/airflow_venv/lib/python3.12/site-packages/airflow/task/task_runner/standard_task_runner.py", line 55, in start
    self.process = self._start_by_fork()
  File "/home/ubuntu/airflow_venv/lib/python3.12/site-packages/airflow/task/task_runner/standard_task_runner.py", line 117, in _start_by_fork
    ret = args.func(args, dag=self.dag)
  File "/home/ubuntu/airflow_venv/lib/python3.12/site-packages/airflow/cli/cli_config.py", line 49, in command
    return func(*args, **kwargs)
  File "/home/ubuntu/airflow_venv/lib/python3.12/site-packages/airflow/utils/cli.py", line 116, in wrapper
    return f(*args, **kwargs)
  File "/home/ubuntu/airflow_venv/lib/python3.12/site-packages/airflow/cli/commands/task_command.py", line 483, in task_run
    task_return_code = _run_task_by_selected_method(args, _dag, ti)
  File "/home/ubuntu/airflow_venv/lib/python3.12/site-packages/airflow/cli/commands/task_command.py", line 256, in _run_task_by_selected_method
    return _run_raw_task(args, ti)
  File "/home/ubuntu/airflow_venv/lib/python3.12/site-packages/airflow/cli/commands/task_command.py", line 341, in _run_raw_task
    return ti._run_raw_task(
  File "/home/ubuntu/airflow_venv/lib/python3.12/site-packages/airflow/utils/session.py", line 97, in wrapper
    return func(*args, session=session, **kwargs)
  File "/home/ubuntu/airflow_venv/lib/python3.12/site-packages/airflow/models/taskinstance.py", line 3006, in _run_raw_task
    return _run_raw_task(
  File "/home/ubuntu/airflow_venv/lib/python3.12/site-packages/airflow/models/taskinstance.py", line 274, in _run_raw_task
    TaskInstance._execute_task_with_callbacks(
  File "/home/ubuntu/airflow_venv/lib/python3.12/site-packages/airflow/models/taskinstance.py", line 3161, in _execute_task_with_callbacks
    result = self._execute_task(context, task_orig)
  File "/home/ubuntu/airflow_venv/lib/python3.12/site-packages/airflow/models/taskinstance.py", line 3185, in _execute_task
    return _execute_task(self, context, task_orig)
  File "/home/ubuntu/airflow_venv/lib/python3.12/site-packages/airflow/models/taskinstance.py", line 768, in _execute_task
    result = _execute_callable(context=context, **execute_callable_kwargs)
  File "/home/ubuntu/airflow_venv/lib/python3.12/site-packages/airflow/models/taskinstance.py", line 734, in _execute_callable
    return ExecutionCallableRunner(
  File "/home/ubuntu/airflow_venv/lib/python3.12/site-packages/airflow/utils/operator_helpers.py", line 252, in run
    return self.func(*args, **kwargs)
  File "/home/ubuntu/airflow_venv/lib/python3.12/site-packages/airflow/models/baseoperator.py", line 424, in wrapper
    return func(self, *args, **kwargs)
  File "/home/ubuntu/airflow_venv/lib/python3.12/site-packages/airflow/providers/http/sensors/http.py", line 169, in execute
    return super().execute(context=context)
  File "/home/ubuntu/airflow_venv/lib/python3.12/site-packages/airflow/models/baseoperator.py", line 424, in wrapper
    return func(self, *args, **kwargs)
  File "/home/ubuntu/airflow_venv/lib/python3.12/site-packages/airflow/sensors/base.py", line 337, in execute
    time.sleep(self._get_next_poke_interval(started_at, run_duration, poke_count))
  File "/home/ubuntu/airflow_venv/lib/python3.12/site-packages/airflow/models/taskinstance.py", line 3095, in signal_handler
    self.log.error("Stacktrace: \n%s", "".join(traceback.format_stack()))

[2025-04-09T13:10:38.358+0000] {taskinstance.py:3313} ERROR - Task failed with exception
Traceback (most recent call last):
  File "/home/ubuntu/airflow_venv/lib/python3.12/site-packages/airflow/models/taskinstance.py", line 768, in _execute_task
    result = _execute_callable(context=context, **execute_callable_kwargs)
             ^^^^^^^^^^^^^^^^^^^^^^^^^^^^^^^^^^^^^^^^^^^^^^^^^^^^^^^^^^^^^
  File "/home/ubuntu/airflow_venv/lib/python3.12/site-packages/airflow/models/taskinstance.py", line 734, in _execute_callable
    return ExecutionCallableRunner(
           ^^^^^^^^^^^^^^^^^^^^^^^^
  File "/home/ubuntu/airflow_venv/lib/python3.12/site-packages/airflow/utils/operator_helpers.py", line 252, in run
    return self.func(*args, **kwargs)
           ^^^^^^^^^^^^^^^^^^^^^^^^^^
  File "/home/ubuntu/airflow_venv/lib/python3.12/site-packages/airflow/models/baseoperator.py", line 424, in wrapper
    return func(self, *args, **kwargs)
           ^^^^^^^^^^^^^^^^^^^^^^^^^^^
  File "/home/ubuntu/airflow_venv/lib/python3.12/site-packages/airflow/providers/http/sensors/http.py", line 169, in execute
    return super().execute(context=context)
           ^^^^^^^^^^^^^^^^^^^^^^^^^^^^^^^^
  File "/home/ubuntu/airflow_venv/lib/python3.12/site-packages/airflow/models/baseoperator.py", line 424, in wrapper
    return func(self, *args, **kwargs)
           ^^^^^^^^^^^^^^^^^^^^^^^^^^^
  File "/home/ubuntu/airflow_venv/lib/python3.12/site-packages/airflow/sensors/base.py", line 337, in execute
    time.sleep(self._get_next_poke_interval(started_at, run_duration, poke_count))
  File "/home/ubuntu/airflow_venv/lib/python3.12/site-packages/airflow/models/taskinstance.py", line 3097, in signal_handler
    raise AirflowTaskTerminated("Task received SIGTERM signal")
airflow.exceptions.AirflowTaskTerminated: Task received SIGTERM signal
[2025-04-09T13:10:38.373+0000] {logging_mixin.py:190} INFO - Task instance in failure state
[2025-04-09T13:10:38.373+0000] {logging_mixin.py:190} INFO - Task start:2025-04-09 12:36:24.289141+00:00 end:2025-04-09 13:10:38.373069+00:00 duration:2054.083928
[2025-04-09T13:10:38.374+0000] {logging_mixin.py:190} INFO - Task:<Task(HttpSensor): is_weather_api_ready> dag:<DAG: weather_dag> dagrun:<DagRun weather_dag @ 2025-04-08 00:00:00+00:00: scheduled__2025-04-08T00:00:00+00:00, state:running, queued_at: 2025-04-09 12:36:21.297601+00:00. externally triggered: False>
[2025-04-09T13:10:38.374+0000] {logging_mixin.py:190} INFO - Failure caused by Task received SIGTERM signal
[2025-04-09T13:10:38.374+0000] {taskinstance.py:1226} INFO - Marking task as UP_FOR_RETRY. dag_id=weather_dag, task_id=is_weather_api_ready, run_id=scheduled__2025-04-08T00:00:00+00:00, execution_date=20250408T000000, start_date=20250409T123624, end_date=20250409T131038
[2025-04-09T13:10:38.417+0000] {taskinstance.py:341} INFO - ::group::Post task execution logs
[2025-04-09T13:10:38.465+0000] {process_utils.py:80} INFO - Process psutil.Process(pid=21868, status='terminated', exitcode=2, started='12:36:24') (21868) terminated with exit code 2
