[2025-04-09T13:26:00.325+0000] {local_task_job_runner.py:123} INFO - ::group::Pre task execution logs
[2025-04-09T13:26:00.337+0000] {taskinstance.py:2614} INFO - Dependencies all met for dep_context=non-requeueable deps ti=<TaskInstance: weather_dag.is_weather_api_ready manual__2025-04-09T13:18:06.700256+00:00 [queued]>
[2025-04-09T13:26:00.344+0000] {taskinstance.py:2614} INFO - Dependencies all met for dep_context=requeueable deps ti=<TaskInstance: weather_dag.is_weather_api_ready manual__2025-04-09T13:18:06.700256+00:00 [queued]>
[2025-04-09T13:26:00.345+0000] {taskinstance.py:2867} INFO - Starting attempt 4 of 3
[2025-04-09T13:26:00.360+0000] {taskinstance.py:2890} INFO - Executing <Task(HttpSensor): is_weather_api_ready> on 2025-04-09 13:18:06.700256+00:00
[2025-04-09T13:26:00.369+0000] {standard_task_runner.py:72} INFO - Started process 23545 to run task
[2025-04-09T13:26:00.374+0000] {standard_task_runner.py:104} INFO - Running: ['airflow', 'tasks', 'run', 'weather_dag', 'is_weather_api_ready', 'manual__2025-04-09T13:18:06.700256+00:00', '--job-id', '23', '--raw', '--subdir', 'DAGS_FOLDER/weather_dag.py', '--cfg-path', '/tmp/tmpkqhna0ly']
[2025-04-09T13:26:00.375+0000] {standard_task_runner.py:105} INFO - Job 23: Subtask is_weather_api_ready
[2025-04-09T13:26:00.422+0000] {task_command.py:467} INFO - Running <TaskInstance: weather_dag.is_weather_api_ready manual__2025-04-09T13:18:06.700256+00:00 [running]> on host ip-172-31-10-226.eu-north-1.compute.internal
[2025-04-09T13:26:00.502+0000] {taskinstance.py:3134} INFO - Exporting env vars: AIRFLOW_CTX_DAG_EMAIL='myemail@domain.com' AIRFLOW_CTX_DAG_OWNER='airflow' AIRFLOW_CTX_DAG_ID='weather_dag' AIRFLOW_CTX_TASK_ID='is_weather_api_ready' AIRFLOW_CTX_EXECUTION_DATE='2025-04-09T13:18:06.700256+00:00' AIRFLOW_CTX_TRY_NUMBER='4' AIRFLOW_CTX_DAG_RUN_ID='manual__2025-04-09T13:18:06.700256+00:00'
[2025-04-09T13:26:00.504+0000] {logging_mixin.py:190} INFO - Task instance is in running state
[2025-04-09T13:26:00.504+0000] {logging_mixin.py:190} INFO -  Previous state of the Task instance: queued
[2025-04-09T13:26:00.504+0000] {logging_mixin.py:190} INFO - Current task name:is_weather_api_ready state:running start_date:2025-04-09 13:26:00.337470+00:00
[2025-04-09T13:26:00.505+0000] {logging_mixin.py:190} INFO - Dag name:weather_dag and current dag run status:running
[2025-04-09T13:26:00.505+0000] {taskinstance.py:732} INFO - ::endgroup::
[2025-04-09T13:26:00.505+0000] {baseoperator.py:423} WARNING - HttpSensor.execute cannot be called outside TaskInstance!
[2025-04-09T13:26:00.506+0000] {http.py:145} INFO - Poking: /data/S2.5/weather?q=Portland&APPID=4d13f07efe491003cd53c704f189b00f
[2025-04-09T13:26:00.512+0000] {base.py:84} INFO - Retrieving connection 'weathermap_api'
[2025-04-09T13:26:00.606+0000] {http.py:278} ERROR - HTTP error: Not Found
[2025-04-09T13:26:00.606+0000] {http.py:279} ERROR - {"cod":"404","message":"Internal error"}
[2025-04-09T13:27:00.607+0000] {http.py:145} INFO - Poking: /data/S2.5/weather?q=Portland&APPID=4d13f07efe491003cd53c704f189b00f
[2025-04-09T13:27:00.611+0000] {base.py:84} INFO - Retrieving connection 'weathermap_api'
[2025-04-09T13:27:00.701+0000] {http.py:278} ERROR - HTTP error: Not Found
[2025-04-09T13:27:00.702+0000] {http.py:279} ERROR - {"cod":"404","message":"Internal error"}
[2025-04-09T13:28:00.703+0000] {http.py:145} INFO - Poking: /data/S2.5/weather?q=Portland&APPID=4d13f07efe491003cd53c704f189b00f
[2025-04-09T13:28:00.706+0000] {base.py:84} INFO - Retrieving connection 'weathermap_api'
[2025-04-09T13:28:00.788+0000] {http.py:278} ERROR - HTTP error: Not Found
[2025-04-09T13:28:00.789+0000] {http.py:279} ERROR - {"cod":"404","message":"Internal error"}
[2025-04-09T13:29:00.789+0000] {http.py:145} INFO - Poking: /data/S2.5/weather?q=Portland&APPID=4d13f07efe491003cd53c704f189b00f
[2025-04-09T13:29:00.793+0000] {base.py:84} INFO - Retrieving connection 'weathermap_api'
[2025-04-09T13:29:00.884+0000] {http.py:278} ERROR - HTTP error: Not Found
[2025-04-09T13:29:00.884+0000] {http.py:279} ERROR - {"cod":"404","message":"Internal error"}
[2025-04-09T13:30:00.886+0000] {http.py:145} INFO - Poking: /data/S2.5/weather?q=Portland&APPID=4d13f07efe491003cd53c704f189b00f
[2025-04-09T13:30:00.888+0000] {base.py:84} INFO - Retrieving connection 'weathermap_api'
[2025-04-09T13:30:00.991+0000] {http.py:278} ERROR - HTTP error: Not Found
[2025-04-09T13:30:00.993+0000] {http.py:279} ERROR - {"cod":"404","message":"Internal error"}
[2025-04-09T13:31:00.994+0000] {http.py:145} INFO - Poking: /data/S2.5/weather?q=Portland&APPID=4d13f07efe491003cd53c704f189b00f
[2025-04-09T13:31:01.003+0000] {base.py:84} INFO - Retrieving connection 'weathermap_api'
[2025-04-09T13:31:01.109+0000] {http.py:278} ERROR - HTTP error: Not Found
[2025-04-09T13:31:01.110+0000] {http.py:279} ERROR - {"cod":"404","message":"Internal error"}
[2025-04-09T13:31:49.014+0000] {local_task_job_runner.py:318} WARNING - Recorded pid 23839 does not match the current pid 23545
[2025-04-09T13:31:49.015+0000] {local_task_job_runner.py:218} WARNING - Heartbeat failed with Exception: PID of job runner does not match
[2025-04-09T13:31:54.069+0000] {local_task_job_runner.py:318} WARNING - Recorded pid 23839 does not match the current pid 23545
[2025-04-09T13:31:54.070+0000] {local_task_job_runner.py:218} WARNING - Heartbeat failed with Exception: PID of job runner does not match
[2025-04-09T13:31:59.121+0000] {local_task_job_runner.py:318} WARNING - Recorded pid 23839 does not match the current pid 23545
[2025-04-09T13:31:59.124+0000] {local_task_job_runner.py:218} WARNING - Heartbeat failed with Exception: PID of job runner does not match
[2025-04-09T13:32:01.110+0000] {http.py:145} INFO - Poking: /data/S2.5/weather?q=Portland&APPID=4d13f07efe491003cd53c704f189b00f
[2025-04-09T13:32:01.113+0000] {base.py:84} INFO - Retrieving connection 'weathermap_api'
[2025-04-09T13:32:01.214+0000] {http.py:278} ERROR - HTTP error: Not Found
[2025-04-09T13:32:01.214+0000] {http.py:279} ERROR - {"cod":"404","message":"Internal error"}
[2025-04-09T13:32:04.142+0000] {local_task_job_runner.py:318} WARNING - Recorded pid 23839 does not match the current pid 23545
[2025-04-09T13:32:04.142+0000] {local_task_job_runner.py:218} WARNING - Heartbeat failed with Exception: PID of job runner does not match
[2025-04-09T13:32:04.685+0000] {local_task_job_runner.py:245} INFO - ::endgroup::
[2025-04-09T13:32:04.690+0000] {process_utils.py:132} INFO - Sending 15 to group 23545. PIDs of all processes in the group: [23545]
[2025-04-09T13:32:04.690+0000] {process_utils.py:87} INFO - Sending the signal 15 to group 23545
[2025-04-09T13:32:04.691+0000] {taskinstance.py:3094} ERROR - Received SIGTERM. Terminating subprocesses.
[2025-04-09T13:32:04.693+0000] {taskinstance.py:3095} ERROR - Stacktrace: 
  File "/home/ubuntu/airflow_venv/bin/airflow", line 8, in <module>
    sys.exit(main())
  File "/home/ubuntu/airflow_venv/lib/python3.12/site-packages/airflow/__main__.py", line 62, in main
    args.func(args)
  File "/home/ubuntu/airflow_venv/lib/python3.12/site-packages/airflow/cli/cli_config.py", line 49, in command
    return func(*args, **kwargs)
  File "/home/ubuntu/airflow_venv/lib/python3.12/site-packages/airflow/utils/cli.py", line 116, in wrapper
    return f(*args, **kwargs)
  File "/home/ubuntu/airflow_venv/lib/python3.12/site-packages/airflow/cli/commands/task_command.py", line 483, in task_run
    task_return_code = _run_task_by_selected_method(args, _dag, ti)
  File "/home/ubuntu/airflow_venv/lib/python3.12/site-packages/airflow/cli/commands/task_command.py", line 254, in _run_task_by_selected_method
    return _run_task_by_local_task_job(args, ti)
  File "/home/ubuntu/airflow_venv/lib/python3.12/site-packages/airflow/cli/commands/task_command.py", line 322, in _run_task_by_local_task_job
    ret = run_job(job=job_runner.job, execute_callable=job_runner._execute)
  File "/home/ubuntu/airflow_venv/lib/python3.12/site-packages/airflow/utils/session.py", line 97, in wrapper
    return func(*args, session=session, **kwargs)
  File "/home/ubuntu/airflow_venv/lib/python3.12/site-packages/airflow/jobs/job.py", line 421, in run_job
    return execute_job(job, execute_callable=execute_callable)
  File "/home/ubuntu/airflow_venv/lib/python3.12/site-packages/airflow/jobs/job.py", line 450, in execute_job
    ret = execute_callable()
  File "/home/ubuntu/airflow_venv/lib/python3.12/site-packages/airflow/jobs/local_task_job_runner.py", line 171, in _execute
    self.task_runner.start()
  File "/home/ubuntu/airflow_venv/lib/python3.12/site-packages/airflow/task/task_runner/standard_task_runner.py", line 55, in start
    self.process = self._start_by_fork()
  File "/home/ubuntu/airflow_venv/lib/python3.12/site-packages/airflow/task/task_runner/standard_task_runner.py", line 117, in _start_by_fork
    ret = args.func(args, dag=self.dag)
  File "/home/ubuntu/airflow_venv/lib/python3.12/site-packages/airflow/cli/cli_config.py", line 49, in command
    return func(*args, **kwargs)
  File "/home/ubuntu/airflow_venv/lib/python3.12/site-packages/airflow/utils/cli.py", line 116, in wrapper
    return f(*args, **kwargs)
  File "/home/ubuntu/airflow_venv/lib/python3.12/site-packages/airflow/cli/commands/task_command.py", line 483, in task_run
    task_return_code = _run_task_by_selected_method(args, _dag, ti)
  File "/home/ubuntu/airflow_venv/lib/python3.12/site-packages/airflow/cli/commands/task_command.py", line 256, in _run_task_by_selected_method
    return _run_raw_task(args, ti)
  File "/home/ubuntu/airflow_venv/lib/python3.12/site-packages/airflow/cli/commands/task_command.py", line 341, in _run_raw_task
    return ti._run_raw_task(
  File "/home/ubuntu/airflow_venv/lib/python3.12/site-packages/airflow/utils/session.py", line 97, in wrapper
    return func(*args, session=session, **kwargs)
  File "/home/ubuntu/airflow_venv/lib/python3.12/site-packages/airflow/models/taskinstance.py", line 3006, in _run_raw_task
    return _run_raw_task(
  File "/home/ubuntu/airflow_venv/lib/python3.12/site-packages/airflow/models/taskinstance.py", line 274, in _run_raw_task
    TaskInstance._execute_task_with_callbacks(
  File "/home/ubuntu/airflow_venv/lib/python3.12/site-packages/airflow/models/taskinstance.py", line 3161, in _execute_task_with_callbacks
    result = self._execute_task(context, task_orig)
  File "/home/ubuntu/airflow_venv/lib/python3.12/site-packages/airflow/models/taskinstance.py", line 3185, in _execute_task
    return _execute_task(self, context, task_orig)
  File "/home/ubuntu/airflow_venv/lib/python3.12/site-packages/airflow/models/taskinstance.py", line 768, in _execute_task
    result = _execute_callable(context=context, **execute_callable_kwargs)
  File "/home/ubuntu/airflow_venv/lib/python3.12/site-packages/airflow/models/taskinstance.py", line 734, in _execute_callable
    return ExecutionCallableRunner(
  File "/home/ubuntu/airflow_venv/lib/python3.12/site-packages/airflow/utils/operator_helpers.py", line 252, in run
    return self.func(*args, **kwargs)
  File "/home/ubuntu/airflow_venv/lib/python3.12/site-packages/airflow/models/baseoperator.py", line 424, in wrapper
    return func(self, *args, **kwargs)
  File "/home/ubuntu/airflow_venv/lib/python3.12/site-packages/airflow/providers/http/sensors/http.py", line 169, in execute
    return super().execute(context=context)
  File "/home/ubuntu/airflow_venv/lib/python3.12/site-packages/airflow/models/baseoperator.py", line 424, in wrapper
    return func(self, *args, **kwargs)
  File "/home/ubuntu/airflow_venv/lib/python3.12/site-packages/airflow/sensors/base.py", line 337, in execute
    time.sleep(self._get_next_poke_interval(started_at, run_duration, poke_count))
  File "/home/ubuntu/airflow_venv/lib/python3.12/site-packages/airflow/models/taskinstance.py", line 3095, in signal_handler
    self.log.error("Stacktrace: \n%s", "".join(traceback.format_stack()))

[2025-04-09T13:32:04.698+0000] {taskinstance.py:3313} ERROR - Task failed with exception
Traceback (most recent call last):
  File "/home/ubuntu/airflow_venv/lib/python3.12/site-packages/airflow/models/taskinstance.py", line 768, in _execute_task
    result = _execute_callable(context=context, **execute_callable_kwargs)
             ^^^^^^^^^^^^^^^^^^^^^^^^^^^^^^^^^^^^^^^^^^^^^^^^^^^^^^^^^^^^^
  File "/home/ubuntu/airflow_venv/lib/python3.12/site-packages/airflow/models/taskinstance.py", line 734, in _execute_callable
    return ExecutionCallableRunner(
           ^^^^^^^^^^^^^^^^^^^^^^^^
  File "/home/ubuntu/airflow_venv/lib/python3.12/site-packages/airflow/utils/operator_helpers.py", line 252, in run
    return self.func(*args, **kwargs)
           ^^^^^^^^^^^^^^^^^^^^^^^^^^
  File "/home/ubuntu/airflow_venv/lib/python3.12/site-packages/airflow/models/baseoperator.py", line 424, in wrapper
    return func(self, *args, **kwargs)
           ^^^^^^^^^^^^^^^^^^^^^^^^^^^
  File "/home/ubuntu/airflow_venv/lib/python3.12/site-packages/airflow/providers/http/sensors/http.py", line 169, in execute
    return super().execute(context=context)
           ^^^^^^^^^^^^^^^^^^^^^^^^^^^^^^^^
  File "/home/ubuntu/airflow_venv/lib/python3.12/site-packages/airflow/models/baseoperator.py", line 424, in wrapper
    return func(self, *args, **kwargs)
           ^^^^^^^^^^^^^^^^^^^^^^^^^^^
  File "/home/ubuntu/airflow_venv/lib/python3.12/site-packages/airflow/sensors/base.py", line 337, in execute
    time.sleep(self._get_next_poke_interval(started_at, run_duration, poke_count))
  File "/home/ubuntu/airflow_venv/lib/python3.12/site-packages/airflow/models/taskinstance.py", line 3097, in signal_handler
    raise AirflowTaskTerminated("Task received SIGTERM signal")
airflow.exceptions.AirflowTaskTerminated: Task received SIGTERM signal
[2025-04-09T13:32:04.701+0000] {logging_mixin.py:190} INFO - Task instance in failure state
[2025-04-09T13:32:04.701+0000] {logging_mixin.py:190} INFO - Task start:2025-04-09 13:31:45.525974+00:00 end:2025-04-09 13:32:04.700858+00:00 duration:19.174884
[2025-04-09T13:32:04.702+0000] {logging_mixin.py:190} INFO - Task:<Task(HttpSensor): is_weather_api_ready> dag:<DAG: weather_dag> dagrun:<DagRun weather_dag @ 2025-04-09 13:18:06.700256+00:00: manual__2025-04-09T13:18:06.700256+00:00, state:running, queued_at: 2025-04-09 13:18:06.726289+00:00. externally triggered: True>
[2025-04-09T13:32:04.702+0000] {logging_mixin.py:190} INFO - Failure caused by Task received SIGTERM signal
[2025-04-09T13:32:04.702+0000] {taskinstance.py:1226} INFO - Marking task as FAILED. dag_id=weather_dag, task_id=is_weather_api_ready, run_id=manual__2025-04-09T13:18:06.700256+00:00, execution_date=20250409T131806, start_date=20250409T133145, end_date=20250409T133204
[2025-04-09T13:32:04.730+0000] {taskinstance.py:341} INFO - ::group::Post task execution logs
[2025-04-09T13:32:04.743+0000] {process_utils.py:80} INFO - Process psutil.Process(pid=23545, status='terminated', exitcode=2, started='13:26:00') (23545) terminated with exit code 2
