[2025-04-09T15:22:38.730+0000] {local_task_job_runner.py:123} INFO - ::group::Pre task execution logs
[2025-04-09T15:22:38.750+0000] {taskinstance.py:2614} INFO - Dependencies all met for dep_context=non-requeueable deps ti=<TaskInstance: weather_dag.is_weather_api_ready manual__2025-04-09T13:43:49.749739+00:00 [queued]>
[2025-04-09T15:22:38.765+0000] {taskinstance.py:2614} INFO - Dependencies all met for dep_context=requeueable deps ti=<TaskInstance: weather_dag.is_weather_api_ready manual__2025-04-09T13:43:49.749739+00:00 [queued]>
[2025-04-09T15:22:38.765+0000] {taskinstance.py:2867} INFO - Starting attempt 3 of 3
[2025-04-09T15:22:38.794+0000] {taskinstance.py:2890} INFO - Executing <Task(HttpSensor): is_weather_api_ready> on 2025-04-09 13:43:49.749739+00:00
[2025-04-09T15:22:38.811+0000] {standard_task_runner.py:72} INFO - Started process 28633 to run task
[2025-04-09T15:22:38.817+0000] {standard_task_runner.py:104} INFO - Running: ['airflow', 'tasks', 'run', 'weather_dag', 'is_weather_api_ready', 'manual__2025-04-09T13:43:49.749739+00:00', '--job-id', '44', '--raw', '--subdir', 'DAGS_FOLDER/weather_dag.py', '--cfg-path', '/tmp/tmpxeg3_a2j']
[2025-04-09T15:22:38.820+0000] {standard_task_runner.py:105} INFO - Job 44: Subtask is_weather_api_ready
[2025-04-09T15:22:38.918+0000] {task_command.py:467} INFO - Running <TaskInstance: weather_dag.is_weather_api_ready manual__2025-04-09T13:43:49.749739+00:00 [running]> on host ip-172-31-10-226.eu-north-1.compute.internal
[2025-04-09T15:22:39.090+0000] {taskinstance.py:3134} INFO - Exporting env vars: AIRFLOW_CTX_DAG_EMAIL='myemail@domain.com' AIRFLOW_CTX_DAG_OWNER='airflow' AIRFLOW_CTX_DAG_ID='weather_dag' AIRFLOW_CTX_TASK_ID='is_weather_api_ready' AIRFLOW_CTX_EXECUTION_DATE='2025-04-09T13:43:49.749739+00:00' AIRFLOW_CTX_TRY_NUMBER='3' AIRFLOW_CTX_DAG_RUN_ID='manual__2025-04-09T13:43:49.749739+00:00'
[2025-04-09T15:22:39.092+0000] {logging_mixin.py:190} INFO - Task instance is in running state
[2025-04-09T15:22:39.093+0000] {logging_mixin.py:190} INFO -  Previous state of the Task instance: queued
[2025-04-09T15:22:39.093+0000] {logging_mixin.py:190} INFO - Current task name:is_weather_api_ready state:running start_date:2025-04-09 15:22:38.750697+00:00
[2025-04-09T15:22:39.093+0000] {logging_mixin.py:190} INFO - Dag name:weather_dag and current dag run status:running
[2025-04-09T15:22:39.095+0000] {taskinstance.py:732} INFO - ::endgroup::
[2025-04-09T15:22:39.095+0000] {baseoperator.py:423} WARNING - HttpSensor.execute cannot be called outside TaskInstance!
[2025-04-09T15:22:39.096+0000] {http.py:145} INFO - Poking: /data/S2.5/weather?q=Portland&APPID=4d13f07efe491003cd53c704f189b00f
[2025-04-09T15:22:39.104+0000] {base.py:84} INFO - Retrieving connection 'weathermap_api'
[2025-04-09T15:22:39.204+0000] {http.py:278} ERROR - HTTP error: Not Found
[2025-04-09T15:22:39.204+0000] {http.py:279} ERROR - {"cod":"404","message":"Internal error"}
[2025-04-09T15:22:43.174+0000] {local_task_job_runner.py:123} INFO - ::group::Pre task execution logs
[2025-04-09T15:22:43.180+0000] {taskinstance.py:2604} INFO - Dependencies not met for <TaskInstance: weather_dag.is_weather_api_ready manual__2025-04-09T13:43:49.749739+00:00 [running]>, dependency 'Task Instance Not Running' FAILED: Task is in the running state
[2025-04-09T15:22:43.181+0000] {taskinstance.py:2604} INFO - Dependencies not met for <TaskInstance: weather_dag.is_weather_api_ready manual__2025-04-09T13:43:49.749739+00:00 [running]>, dependency 'Task Instance State' FAILED: Task is in the 'running' state.
[2025-04-09T15:22:43.187+0000] {local_task_job_runner.py:166} INFO - Task is not able to be run
[2025-04-09T15:23:39.205+0000] {http.py:145} INFO - Poking: /data/S2.5/weather?q=Portland&APPID=4d13f07efe491003cd53c704f189b00f
[2025-04-09T15:23:39.209+0000] {base.py:84} INFO - Retrieving connection 'weathermap_api'
[2025-04-09T15:23:39.322+0000] {http.py:278} ERROR - HTTP error: Not Found
[2025-04-09T15:23:39.323+0000] {http.py:279} ERROR - {"cod":"404","message":"Internal error"}
[2025-04-09T15:24:39.324+0000] {http.py:145} INFO - Poking: /data/S2.5/weather?q=Portland&APPID=4d13f07efe491003cd53c704f189b00f
[2025-04-09T15:24:39.334+0000] {base.py:84} INFO - Retrieving connection 'weathermap_api'
[2025-04-09T15:24:39.433+0000] {http.py:278} ERROR - HTTP error: Not Found
[2025-04-09T15:24:39.434+0000] {http.py:279} ERROR - {"cod":"404","message":"Internal error"}
[2025-04-09T15:24:44.911+0000] {local_task_job_runner.py:318} WARNING - Recorded pid 29291 does not match the current pid 28633
[2025-04-09T15:24:44.912+0000] {local_task_job_runner.py:218} WARNING - Heartbeat failed with Exception: PID of job runner does not match
[2025-04-09T15:24:49.943+0000] {local_task_job_runner.py:318} WARNING - Recorded pid 29291 does not match the current pid 28633
[2025-04-09T15:24:49.944+0000] {local_task_job_runner.py:218} WARNING - Heartbeat failed with Exception: PID of job runner does not match
[2025-04-09T15:24:55.001+0000] {local_task_job_runner.py:318} WARNING - Recorded pid 29291 does not match the current pid 28633
[2025-04-09T15:24:55.003+0000] {local_task_job_runner.py:218} WARNING - Heartbeat failed with Exception: PID of job runner does not match
[2025-04-09T15:25:00.068+0000] {local_task_job_runner.py:318} WARNING - Recorded pid 29291 does not match the current pid 28633
[2025-04-09T15:25:00.069+0000] {local_task_job_runner.py:218} WARNING - Heartbeat failed with Exception: PID of job runner does not match
[2025-04-09T15:25:05.119+0000] {local_task_job_runner.py:318} WARNING - Recorded pid 29291 does not match the current pid 28633
[2025-04-09T15:25:05.121+0000] {local_task_job_runner.py:218} WARNING - Heartbeat failed with Exception: PID of job runner does not match
[2025-04-09T15:25:10.171+0000] {local_task_job_runner.py:318} WARNING - Recorded pid 29291 does not match the current pid 28633
[2025-04-09T15:25:10.173+0000] {local_task_job_runner.py:218} WARNING - Heartbeat failed with Exception: PID of job runner does not match
[2025-04-09T15:25:15.235+0000] {local_task_job_runner.py:318} WARNING - Recorded pid 29291 does not match the current pid 28633
[2025-04-09T15:25:15.235+0000] {local_task_job_runner.py:218} WARNING - Heartbeat failed with Exception: PID of job runner does not match
[2025-04-09T15:25:20.294+0000] {local_task_job_runner.py:318} WARNING - Recorded pid 29291 does not match the current pid 28633
[2025-04-09T15:25:20.295+0000] {local_task_job_runner.py:218} WARNING - Heartbeat failed with Exception: PID of job runner does not match
[2025-04-09T15:25:25.349+0000] {local_task_job_runner.py:318} WARNING - Recorded pid 29291 does not match the current pid 28633
[2025-04-09T15:25:25.350+0000] {local_task_job_runner.py:218} WARNING - Heartbeat failed with Exception: PID of job runner does not match
[2025-04-09T15:25:30.397+0000] {local_task_job_runner.py:318} WARNING - Recorded pid 29291 does not match the current pid 28633
[2025-04-09T15:25:30.398+0000] {local_task_job_runner.py:218} WARNING - Heartbeat failed with Exception: PID of job runner does not match
[2025-04-09T15:25:35.452+0000] {local_task_job_runner.py:318} WARNING - Recorded pid 29291 does not match the current pid 28633
[2025-04-09T15:25:35.454+0000] {local_task_job_runner.py:218} WARNING - Heartbeat failed with Exception: PID of job runner does not match
[2025-04-09T15:25:39.435+0000] {http.py:145} INFO - Poking: /data/S2.5/weather?q=Portland&APPID=4d13f07efe491003cd53c704f189b00f
[2025-04-09T15:25:39.439+0000] {base.py:84} INFO - Retrieving connection 'weathermap_api'
[2025-04-09T15:25:39.529+0000] {http.py:278} ERROR - HTTP error: Not Found
[2025-04-09T15:25:39.530+0000] {http.py:279} ERROR - {"cod":"404","message":"Internal error"}
[2025-04-09T15:25:40.507+0000] {local_task_job_runner.py:318} WARNING - Recorded pid 29291 does not match the current pid 28633
[2025-04-09T15:25:40.508+0000] {local_task_job_runner.py:218} WARNING - Heartbeat failed with Exception: PID of job runner does not match
[2025-04-09T15:25:45.555+0000] {local_task_job_runner.py:318} WARNING - Recorded pid 29291 does not match the current pid 28633
[2025-04-09T15:25:45.555+0000] {local_task_job_runner.py:218} WARNING - Heartbeat failed with Exception: PID of job runner does not match
[2025-04-09T15:25:50.610+0000] {local_task_job_runner.py:318} WARNING - Recorded pid 29291 does not match the current pid 28633
[2025-04-09T15:25:50.611+0000] {local_task_job_runner.py:218} WARNING - Heartbeat failed with Exception: PID of job runner does not match
[2025-04-09T15:25:55.668+0000] {local_task_job_runner.py:318} WARNING - Recorded pid 29291 does not match the current pid 28633
[2025-04-09T15:25:55.669+0000] {local_task_job_runner.py:218} WARNING - Heartbeat failed with Exception: PID of job runner does not match
[2025-04-09T15:26:00.732+0000] {local_task_job_runner.py:318} WARNING - Recorded pid 29291 does not match the current pid 28633
[2025-04-09T15:26:00.735+0000] {local_task_job_runner.py:218} WARNING - Heartbeat failed with Exception: PID of job runner does not match
[2025-04-09T15:26:05.792+0000] {local_task_job_runner.py:318} WARNING - Recorded pid 29291 does not match the current pid 28633
[2025-04-09T15:26:05.793+0000] {local_task_job_runner.py:218} WARNING - Heartbeat failed with Exception: PID of job runner does not match
[2025-04-09T15:26:10.843+0000] {local_task_job_runner.py:318} WARNING - Recorded pid 29291 does not match the current pid 28633
[2025-04-09T15:26:10.844+0000] {local_task_job_runner.py:218} WARNING - Heartbeat failed with Exception: PID of job runner does not match
[2025-04-09T15:26:15.909+0000] {local_task_job_runner.py:318} WARNING - Recorded pid 29291 does not match the current pid 28633
[2025-04-09T15:26:15.912+0000] {local_task_job_runner.py:218} WARNING - Heartbeat failed with Exception: PID of job runner does not match
[2025-04-09T15:26:20.960+0000] {local_task_job_runner.py:318} WARNING - Recorded pid 29291 does not match the current pid 28633
[2025-04-09T15:26:20.961+0000] {local_task_job_runner.py:218} WARNING - Heartbeat failed with Exception: PID of job runner does not match
[2025-04-09T15:26:26.027+0000] {local_task_job_runner.py:318} WARNING - Recorded pid 29291 does not match the current pid 28633
[2025-04-09T15:26:26.028+0000] {local_task_job_runner.py:218} WARNING - Heartbeat failed with Exception: PID of job runner does not match
[2025-04-09T15:26:31.075+0000] {local_task_job_runner.py:318} WARNING - Recorded pid 29291 does not match the current pid 28633
[2025-04-09T15:26:31.075+0000] {local_task_job_runner.py:218} WARNING - Heartbeat failed with Exception: PID of job runner does not match
[2025-04-09T15:26:36.127+0000] {local_task_job_runner.py:318} WARNING - Recorded pid 29291 does not match the current pid 28633
[2025-04-09T15:26:36.128+0000] {local_task_job_runner.py:218} WARNING - Heartbeat failed with Exception: PID of job runner does not match
[2025-04-09T15:26:39.531+0000] {http.py:145} INFO - Poking: /data/S2.5/weather?q=Portland&APPID=4d13f07efe491003cd53c704f189b00f
[2025-04-09T15:26:39.537+0000] {base.py:84} INFO - Retrieving connection 'weathermap_api'
[2025-04-09T15:26:39.624+0000] {http.py:278} ERROR - HTTP error: Not Found
[2025-04-09T15:26:39.624+0000] {http.py:279} ERROR - {"cod":"404","message":"Internal error"}
[2025-04-09T15:26:41.186+0000] {local_task_job_runner.py:318} WARNING - Recorded pid 29291 does not match the current pid 28633
[2025-04-09T15:26:41.190+0000] {local_task_job_runner.py:218} WARNING - Heartbeat failed with Exception: PID of job runner does not match
[2025-04-09T15:26:46.250+0000] {local_task_job_runner.py:318} WARNING - Recorded pid 29291 does not match the current pid 28633
[2025-04-09T15:26:46.251+0000] {local_task_job_runner.py:218} WARNING - Heartbeat failed with Exception: PID of job runner does not match
[2025-04-09T15:26:51.303+0000] {local_task_job_runner.py:318} WARNING - Recorded pid 29291 does not match the current pid 28633
[2025-04-09T15:26:51.304+0000] {local_task_job_runner.py:218} WARNING - Heartbeat failed with Exception: PID of job runner does not match
[2025-04-09T15:26:56.351+0000] {local_task_job_runner.py:318} WARNING - Recorded pid 29291 does not match the current pid 28633
[2025-04-09T15:26:56.352+0000] {local_task_job_runner.py:218} WARNING - Heartbeat failed with Exception: PID of job runner does not match
[2025-04-09T15:27:01.412+0000] {local_task_job_runner.py:318} WARNING - Recorded pid 29291 does not match the current pid 28633
[2025-04-09T15:27:01.412+0000] {local_task_job_runner.py:218} WARNING - Heartbeat failed with Exception: PID of job runner does not match
[2025-04-09T15:27:06.465+0000] {local_task_job_runner.py:318} WARNING - Recorded pid 29291 does not match the current pid 28633
[2025-04-09T15:27:06.466+0000] {local_task_job_runner.py:218} WARNING - Heartbeat failed with Exception: PID of job runner does not match
[2025-04-09T15:27:11.513+0000] {local_task_job_runner.py:318} WARNING - Recorded pid 29291 does not match the current pid 28633
[2025-04-09T15:27:11.513+0000] {local_task_job_runner.py:218} WARNING - Heartbeat failed with Exception: PID of job runner does not match
[2025-04-09T15:27:16.562+0000] {local_task_job_runner.py:318} WARNING - Recorded pid 29291 does not match the current pid 28633
[2025-04-09T15:27:16.562+0000] {local_task_job_runner.py:218} WARNING - Heartbeat failed with Exception: PID of job runner does not match
[2025-04-09T15:27:21.617+0000] {local_task_job_runner.py:318} WARNING - Recorded pid 29291 does not match the current pid 28633
[2025-04-09T15:27:21.617+0000] {local_task_job_runner.py:218} WARNING - Heartbeat failed with Exception: PID of job runner does not match
[2025-04-09T15:27:26.680+0000] {local_task_job_runner.py:318} WARNING - Recorded pid 29291 does not match the current pid 28633
[2025-04-09T15:27:26.681+0000] {local_task_job_runner.py:218} WARNING - Heartbeat failed with Exception: PID of job runner does not match
[2025-04-09T15:27:31.732+0000] {local_task_job_runner.py:318} WARNING - Recorded pid 29291 does not match the current pid 28633
[2025-04-09T15:27:31.734+0000] {local_task_job_runner.py:218} WARNING - Heartbeat failed with Exception: PID of job runner does not match
[2025-04-09T15:27:36.794+0000] {local_task_job_runner.py:318} WARNING - Recorded pid 29291 does not match the current pid 28633
[2025-04-09T15:27:36.794+0000] {local_task_job_runner.py:218} WARNING - Heartbeat failed with Exception: PID of job runner does not match
[2025-04-09T15:27:39.625+0000] {http.py:145} INFO - Poking: /data/S2.5/weather?q=Portland&APPID=4d13f07efe491003cd53c704f189b00f
[2025-04-09T15:27:39.628+0000] {base.py:84} INFO - Retrieving connection 'weathermap_api'
[2025-04-09T15:27:39.714+0000] {http.py:278} ERROR - HTTP error: Not Found
[2025-04-09T15:27:39.715+0000] {http.py:279} ERROR - {"cod":"404","message":"Internal error"}
[2025-04-09T15:27:41.850+0000] {local_task_job_runner.py:318} WARNING - Recorded pid 29291 does not match the current pid 28633
[2025-04-09T15:27:41.852+0000] {local_task_job_runner.py:218} WARNING - Heartbeat failed with Exception: PID of job runner does not match
[2025-04-09T15:27:46.900+0000] {local_task_job_runner.py:318} WARNING - Recorded pid 29291 does not match the current pid 28633
[2025-04-09T15:27:46.911+0000] {local_task_job_runner.py:218} WARNING - Heartbeat failed with Exception: PID of job runner does not match
[2025-04-09T15:27:51.959+0000] {local_task_job_runner.py:318} WARNING - Recorded pid 29291 does not match the current pid 28633
[2025-04-09T15:27:51.959+0000] {local_task_job_runner.py:218} WARNING - Heartbeat failed with Exception: PID of job runner does not match
[2025-04-09T15:27:57.011+0000] {local_task_job_runner.py:318} WARNING - Recorded pid 29291 does not match the current pid 28633
[2025-04-09T15:27:57.012+0000] {local_task_job_runner.py:218} WARNING - Heartbeat failed with Exception: PID of job runner does not match
[2025-04-09T15:28:02.069+0000] {local_task_job_runner.py:318} WARNING - Recorded pid 29291 does not match the current pid 28633
[2025-04-09T15:28:02.069+0000] {local_task_job_runner.py:218} WARNING - Heartbeat failed with Exception: PID of job runner does not match
[2025-04-09T15:28:07.094+0000] {local_task_job_runner.py:318} WARNING - Recorded pid 29291 does not match the current pid 28633
[2025-04-09T15:28:07.094+0000] {local_task_job_runner.py:218} WARNING - Heartbeat failed with Exception: PID of job runner does not match
[2025-04-09T15:28:12.145+0000] {local_task_job_runner.py:318} WARNING - Recorded pid 29291 does not match the current pid 28633
[2025-04-09T15:28:12.145+0000] {local_task_job_runner.py:218} WARNING - Heartbeat failed with Exception: PID of job runner does not match
[2025-04-09T15:28:17.195+0000] {local_task_job_runner.py:318} WARNING - Recorded pid 29291 does not match the current pid 28633
[2025-04-09T15:28:17.196+0000] {local_task_job_runner.py:218} WARNING - Heartbeat failed with Exception: PID of job runner does not match
[2025-04-09T15:28:22.245+0000] {local_task_job_runner.py:318} WARNING - Recorded pid 29291 does not match the current pid 28633
[2025-04-09T15:28:22.246+0000] {local_task_job_runner.py:218} WARNING - Heartbeat failed with Exception: PID of job runner does not match
[2025-04-09T15:28:27.298+0000] {local_task_job_runner.py:318} WARNING - Recorded pid 29291 does not match the current pid 28633
[2025-04-09T15:28:27.304+0000] {local_task_job_runner.py:218} WARNING - Heartbeat failed with Exception: PID of job runner does not match
[2025-04-09T15:28:32.323+0000] {local_task_job_runner.py:318} WARNING - Recorded pid 29291 does not match the current pid 28633
[2025-04-09T15:28:32.324+0000] {local_task_job_runner.py:218} WARNING - Heartbeat failed with Exception: PID of job runner does not match
[2025-04-09T15:28:37.376+0000] {local_task_job_runner.py:318} WARNING - Recorded pid 29291 does not match the current pid 28633
[2025-04-09T15:28:37.376+0000] {local_task_job_runner.py:218} WARNING - Heartbeat failed with Exception: PID of job runner does not match
[2025-04-09T15:28:39.716+0000] {http.py:145} INFO - Poking: /data/S2.5/weather?q=Portland&APPID=4d13f07efe491003cd53c704f189b00f
[2025-04-09T15:28:39.722+0000] {base.py:84} INFO - Retrieving connection 'weathermap_api'
[2025-04-09T15:28:39.813+0000] {http.py:278} ERROR - HTTP error: Not Found
[2025-04-09T15:28:39.814+0000] {http.py:279} ERROR - {"cod":"404","message":"Internal error"}
[2025-04-09T15:28:42.438+0000] {local_task_job_runner.py:318} WARNING - Recorded pid 29291 does not match the current pid 28633
[2025-04-09T15:28:42.438+0000] {local_task_job_runner.py:218} WARNING - Heartbeat failed with Exception: PID of job runner does not match
[2025-04-09T15:28:47.497+0000] {local_task_job_runner.py:318} WARNING - Recorded pid 29291 does not match the current pid 28633
[2025-04-09T15:28:47.497+0000] {local_task_job_runner.py:218} WARNING - Heartbeat failed with Exception: PID of job runner does not match
[2025-04-09T15:28:52.557+0000] {local_task_job_runner.py:318} WARNING - Recorded pid 29291 does not match the current pid 28633
[2025-04-09T15:28:52.557+0000] {local_task_job_runner.py:218} WARNING - Heartbeat failed with Exception: PID of job runner does not match
[2025-04-09T15:28:57.616+0000] {local_task_job_runner.py:318} WARNING - Recorded pid 29291 does not match the current pid 28633
[2025-04-09T15:28:57.617+0000] {local_task_job_runner.py:218} WARNING - Heartbeat failed with Exception: PID of job runner does not match
[2025-04-09T15:29:02.666+0000] {local_task_job_runner.py:318} WARNING - Recorded pid 29291 does not match the current pid 28633
[2025-04-09T15:29:02.667+0000] {local_task_job_runner.py:218} WARNING - Heartbeat failed with Exception: PID of job runner does not match
[2025-04-09T15:29:07.714+0000] {local_task_job_runner.py:318} WARNING - Recorded pid 29291 does not match the current pid 28633
[2025-04-09T15:29:07.714+0000] {local_task_job_runner.py:218} WARNING - Heartbeat failed with Exception: PID of job runner does not match
[2025-04-09T15:29:12.777+0000] {local_task_job_runner.py:318} WARNING - Recorded pid 29291 does not match the current pid 28633
[2025-04-09T15:29:12.779+0000] {local_task_job_runner.py:218} WARNING - Heartbeat failed with Exception: PID of job runner does not match
[2025-04-09T15:29:17.800+0000] {local_task_job_runner.py:318} WARNING - Recorded pid 29291 does not match the current pid 28633
[2025-04-09T15:29:17.801+0000] {local_task_job_runner.py:218} WARNING - Heartbeat failed with Exception: PID of job runner does not match
[2025-04-09T15:29:22.851+0000] {local_task_job_runner.py:318} WARNING - Recorded pid 29291 does not match the current pid 28633
[2025-04-09T15:29:22.851+0000] {local_task_job_runner.py:218} WARNING - Heartbeat failed with Exception: PID of job runner does not match
[2025-04-09T15:29:27.902+0000] {local_task_job_runner.py:318} WARNING - Recorded pid 29291 does not match the current pid 28633
[2025-04-09T15:29:27.902+0000] {local_task_job_runner.py:218} WARNING - Heartbeat failed with Exception: PID of job runner does not match
[2025-04-09T15:29:32.950+0000] {local_task_job_runner.py:318} WARNING - Recorded pid 29291 does not match the current pid 28633
[2025-04-09T15:29:32.950+0000] {local_task_job_runner.py:218} WARNING - Heartbeat failed with Exception: PID of job runner does not match
[2025-04-09T15:29:38.003+0000] {local_task_job_runner.py:318} WARNING - Recorded pid 29291 does not match the current pid 28633
[2025-04-09T15:29:38.004+0000] {local_task_job_runner.py:218} WARNING - Heartbeat failed with Exception: PID of job runner does not match
[2025-04-09T15:29:39.815+0000] {http.py:145} INFO - Poking: /data/S2.5/weather?q=Portland&APPID=4d13f07efe491003cd53c704f189b00f
[2025-04-09T15:29:39.819+0000] {base.py:84} INFO - Retrieving connection 'weathermap_api'
[2025-04-09T15:29:39.901+0000] {http.py:278} ERROR - HTTP error: Not Found
[2025-04-09T15:29:39.902+0000] {http.py:279} ERROR - {"cod":"404","message":"Internal error"}
[2025-04-09T15:29:43.052+0000] {local_task_job_runner.py:318} WARNING - Recorded pid 29291 does not match the current pid 28633
[2025-04-09T15:29:43.053+0000] {local_task_job_runner.py:218} WARNING - Heartbeat failed with Exception: PID of job runner does not match
[2025-04-09T15:29:48.103+0000] {local_task_job_runner.py:318} WARNING - Recorded pid 29291 does not match the current pid 28633
[2025-04-09T15:29:48.103+0000] {local_task_job_runner.py:218} WARNING - Heartbeat failed with Exception: PID of job runner does not match
[2025-04-09T15:29:53.156+0000] {local_task_job_runner.py:318} WARNING - Recorded pid 29291 does not match the current pid 28633
[2025-04-09T15:29:53.158+0000] {local_task_job_runner.py:218} WARNING - Heartbeat failed with Exception: PID of job runner does not match
[2025-04-09T15:29:58.210+0000] {local_task_job_runner.py:318} WARNING - Recorded pid 29291 does not match the current pid 28633
[2025-04-09T15:29:58.210+0000] {local_task_job_runner.py:218} WARNING - Heartbeat failed with Exception: PID of job runner does not match
[2025-04-09T15:30:03.264+0000] {local_task_job_runner.py:318} WARNING - Recorded pid 29291 does not match the current pid 28633
[2025-04-09T15:30:03.265+0000] {local_task_job_runner.py:218} WARNING - Heartbeat failed with Exception: PID of job runner does not match
[2025-04-09T15:30:08.330+0000] {local_task_job_runner.py:318} WARNING - Recorded pid 29291 does not match the current pid 28633
[2025-04-09T15:30:08.331+0000] {local_task_job_runner.py:218} WARNING - Heartbeat failed with Exception: PID of job runner does not match
[2025-04-09T15:30:13.388+0000] {local_task_job_runner.py:318} WARNING - Recorded pid 29291 does not match the current pid 28633
[2025-04-09T15:30:13.390+0000] {local_task_job_runner.py:218} WARNING - Heartbeat failed with Exception: PID of job runner does not match
[2025-04-09T15:30:18.440+0000] {local_task_job_runner.py:318} WARNING - Recorded pid 29291 does not match the current pid 28633
[2025-04-09T15:30:18.441+0000] {local_task_job_runner.py:218} WARNING - Heartbeat failed with Exception: PID of job runner does not match
[2025-04-09T15:30:23.488+0000] {local_task_job_runner.py:318} WARNING - Recorded pid 29291 does not match the current pid 28633
[2025-04-09T15:30:23.490+0000] {local_task_job_runner.py:218} WARNING - Heartbeat failed with Exception: PID of job runner does not match
[2025-04-09T15:30:28.539+0000] {local_task_job_runner.py:318} WARNING - Recorded pid 29291 does not match the current pid 28633
[2025-04-09T15:30:28.539+0000] {local_task_job_runner.py:218} WARNING - Heartbeat failed with Exception: PID of job runner does not match
[2025-04-09T15:30:33.585+0000] {local_task_job_runner.py:318} WARNING - Recorded pid 29291 does not match the current pid 28633
[2025-04-09T15:30:33.586+0000] {local_task_job_runner.py:218} WARNING - Heartbeat failed with Exception: PID of job runner does not match
[2025-04-09T15:30:38.632+0000] {local_task_job_runner.py:318} WARNING - Recorded pid 29291 does not match the current pid 28633
[2025-04-09T15:30:38.633+0000] {local_task_job_runner.py:218} WARNING - Heartbeat failed with Exception: PID of job runner does not match
[2025-04-09T15:30:39.903+0000] {http.py:145} INFO - Poking: /data/S2.5/weather?q=Portland&APPID=4d13f07efe491003cd53c704f189b00f
[2025-04-09T15:30:39.908+0000] {base.py:84} INFO - Retrieving connection 'weathermap_api'
[2025-04-09T15:30:39.998+0000] {http.py:278} ERROR - HTTP error: Not Found
[2025-04-09T15:30:39.999+0000] {http.py:279} ERROR - {"cod":"404","message":"Internal error"}
[2025-04-09T15:30:43.685+0000] {local_task_job_runner.py:318} WARNING - Recorded pid 29291 does not match the current pid 28633
[2025-04-09T15:30:43.686+0000] {local_task_job_runner.py:218} WARNING - Heartbeat failed with Exception: PID of job runner does not match
[2025-04-09T15:30:48.732+0000] {local_task_job_runner.py:318} WARNING - Recorded pid 29291 does not match the current pid 28633
[2025-04-09T15:30:48.732+0000] {local_task_job_runner.py:218} WARNING - Heartbeat failed with Exception: PID of job runner does not match
[2025-04-09T15:30:53.796+0000] {local_task_job_runner.py:318} WARNING - Recorded pid 29291 does not match the current pid 28633
[2025-04-09T15:30:53.800+0000] {local_task_job_runner.py:218} WARNING - Heartbeat failed with Exception: PID of job runner does not match
[2025-04-09T15:30:58.848+0000] {local_task_job_runner.py:318} WARNING - Recorded pid 29291 does not match the current pid 28633
[2025-04-09T15:30:58.848+0000] {local_task_job_runner.py:218} WARNING - Heartbeat failed with Exception: PID of job runner does not match
[2025-04-09T15:31:03.897+0000] {local_task_job_runner.py:318} WARNING - Recorded pid 29291 does not match the current pid 28633
[2025-04-09T15:31:03.898+0000] {local_task_job_runner.py:218} WARNING - Heartbeat failed with Exception: PID of job runner does not match
[2025-04-09T15:31:08.947+0000] {local_task_job_runner.py:318} WARNING - Recorded pid 29291 does not match the current pid 28633
[2025-04-09T15:31:08.947+0000] {local_task_job_runner.py:218} WARNING - Heartbeat failed with Exception: PID of job runner does not match
[2025-04-09T15:31:14.026+0000] {local_task_job_runner.py:318} WARNING - Recorded pid 29291 does not match the current pid 28633
[2025-04-09T15:31:14.027+0000] {local_task_job_runner.py:218} WARNING - Heartbeat failed with Exception: PID of job runner does not match
[2025-04-09T15:31:19.084+0000] {local_task_job_runner.py:318} WARNING - Recorded pid 29291 does not match the current pid 28633
[2025-04-09T15:31:19.084+0000] {local_task_job_runner.py:218} WARNING - Heartbeat failed with Exception: PID of job runner does not match
[2025-04-09T15:31:24.133+0000] {local_task_job_runner.py:318} WARNING - Recorded pid 29291 does not match the current pid 28633
[2025-04-09T15:31:24.136+0000] {local_task_job_runner.py:218} WARNING - Heartbeat failed with Exception: PID of job runner does not match
[2025-04-09T15:31:29.186+0000] {local_task_job_runner.py:318} WARNING - Recorded pid 29291 does not match the current pid 28633
[2025-04-09T15:31:29.187+0000] {local_task_job_runner.py:218} WARNING - Heartbeat failed with Exception: PID of job runner does not match
[2025-04-09T15:31:34.239+0000] {local_task_job_runner.py:318} WARNING - Recorded pid 29291 does not match the current pid 28633
[2025-04-09T15:31:34.240+0000] {local_task_job_runner.py:218} WARNING - Heartbeat failed with Exception: PID of job runner does not match
[2025-04-09T15:31:39.294+0000] {local_task_job_runner.py:318} WARNING - Recorded pid 29291 does not match the current pid 28633
[2025-04-09T15:31:39.295+0000] {local_task_job_runner.py:218} WARNING - Heartbeat failed with Exception: PID of job runner does not match
[2025-04-09T15:31:40.000+0000] {http.py:145} INFO - Poking: /data/S2.5/weather?q=Portland&APPID=4d13f07efe491003cd53c704f189b00f
[2025-04-09T15:31:40.003+0000] {base.py:84} INFO - Retrieving connection 'weathermap_api'
[2025-04-09T15:31:40.095+0000] {http.py:278} ERROR - HTTP error: Not Found
[2025-04-09T15:31:40.095+0000] {http.py:279} ERROR - {"cod":"404","message":"Internal error"}
[2025-04-09T15:31:44.349+0000] {local_task_job_runner.py:318} WARNING - Recorded pid 29291 does not match the current pid 28633
[2025-04-09T15:31:44.350+0000] {local_task_job_runner.py:218} WARNING - Heartbeat failed with Exception: PID of job runner does not match
[2025-04-09T15:31:49.367+0000] {local_task_job_runner.py:318} WARNING - Recorded pid 29291 does not match the current pid 28633
[2025-04-09T15:31:49.368+0000] {local_task_job_runner.py:218} WARNING - Heartbeat failed with Exception: PID of job runner does not match
[2025-04-09T15:31:54.421+0000] {local_task_job_runner.py:318} WARNING - Recorded pid 29291 does not match the current pid 28633
[2025-04-09T15:31:54.422+0000] {local_task_job_runner.py:218} WARNING - Heartbeat failed with Exception: PID of job runner does not match
[2025-04-09T15:31:59.476+0000] {local_task_job_runner.py:318} WARNING - Recorded pid 29291 does not match the current pid 28633
[2025-04-09T15:31:59.477+0000] {local_task_job_runner.py:218} WARNING - Heartbeat failed with Exception: PID of job runner does not match
[2025-04-09T15:32:04.538+0000] {local_task_job_runner.py:318} WARNING - Recorded pid 29291 does not match the current pid 28633
[2025-04-09T15:32:04.539+0000] {local_task_job_runner.py:218} WARNING - Heartbeat failed with Exception: PID of job runner does not match
[2025-04-09T15:32:09.604+0000] {local_task_job_runner.py:318} WARNING - Recorded pid 29291 does not match the current pid 28633
[2025-04-09T15:32:09.605+0000] {local_task_job_runner.py:218} WARNING - Heartbeat failed with Exception: PID of job runner does not match
[2025-04-09T15:32:14.668+0000] {local_task_job_runner.py:318} WARNING - Recorded pid 29291 does not match the current pid 28633
[2025-04-09T15:32:14.670+0000] {local_task_job_runner.py:218} WARNING - Heartbeat failed with Exception: PID of job runner does not match
[2025-04-09T15:32:19.724+0000] {local_task_job_runner.py:318} WARNING - Recorded pid 29291 does not match the current pid 28633
[2025-04-09T15:32:19.724+0000] {local_task_job_runner.py:218} WARNING - Heartbeat failed with Exception: PID of job runner does not match
[2025-04-09T15:32:24.778+0000] {local_task_job_runner.py:318} WARNING - Recorded pid 29291 does not match the current pid 28633
[2025-04-09T15:32:24.779+0000] {local_task_job_runner.py:218} WARNING - Heartbeat failed with Exception: PID of job runner does not match
[2025-04-09T15:32:29.834+0000] {local_task_job_runner.py:318} WARNING - Recorded pid 29291 does not match the current pid 28633
[2025-04-09T15:32:29.834+0000] {local_task_job_runner.py:218} WARNING - Heartbeat failed with Exception: PID of job runner does not match
[2025-04-09T15:32:34.889+0000] {local_task_job_runner.py:318} WARNING - Recorded pid 29291 does not match the current pid 28633
[2025-04-09T15:32:34.890+0000] {local_task_job_runner.py:218} WARNING - Heartbeat failed with Exception: PID of job runner does not match
[2025-04-09T15:32:39.942+0000] {local_task_job_runner.py:318} WARNING - Recorded pid 29291 does not match the current pid 28633
[2025-04-09T15:32:39.943+0000] {local_task_job_runner.py:218} WARNING - Heartbeat failed with Exception: PID of job runner does not match
[2025-04-09T15:32:40.096+0000] {http.py:145} INFO - Poking: /data/S2.5/weather?q=Portland&APPID=4d13f07efe491003cd53c704f189b00f
[2025-04-09T15:32:40.099+0000] {base.py:84} INFO - Retrieving connection 'weathermap_api'
[2025-04-09T15:32:40.202+0000] {http.py:278} ERROR - HTTP error: Not Found
[2025-04-09T15:32:40.202+0000] {http.py:279} ERROR - {"cod":"404","message":"Internal error"}
[2025-04-09T15:32:44.991+0000] {local_task_job_runner.py:318} WARNING - Recorded pid 29291 does not match the current pid 28633
[2025-04-09T15:32:44.991+0000] {local_task_job_runner.py:218} WARNING - Heartbeat failed with Exception: PID of job runner does not match
[2025-04-09T15:32:50.045+0000] {local_task_job_runner.py:318} WARNING - Recorded pid 29291 does not match the current pid 28633
[2025-04-09T15:32:50.045+0000] {local_task_job_runner.py:218} WARNING - Heartbeat failed with Exception: PID of job runner does not match
[2025-04-09T15:32:55.098+0000] {local_task_job_runner.py:318} WARNING - Recorded pid 29291 does not match the current pid 28633
[2025-04-09T15:32:55.099+0000] {local_task_job_runner.py:218} WARNING - Heartbeat failed with Exception: PID of job runner does not match
[2025-04-09T15:33:00.153+0000] {local_task_job_runner.py:318} WARNING - Recorded pid 29291 does not match the current pid 28633
[2025-04-09T15:33:00.153+0000] {local_task_job_runner.py:218} WARNING - Heartbeat failed with Exception: PID of job runner does not match
[2025-04-09T15:33:05.209+0000] {local_task_job_runner.py:318} WARNING - Recorded pid 29291 does not match the current pid 28633
[2025-04-09T15:33:05.210+0000] {local_task_job_runner.py:218} WARNING - Heartbeat failed with Exception: PID of job runner does not match
[2025-04-09T15:33:10.263+0000] {local_task_job_runner.py:318} WARNING - Recorded pid 29291 does not match the current pid 28633
[2025-04-09T15:33:10.264+0000] {local_task_job_runner.py:218} WARNING - Heartbeat failed with Exception: PID of job runner does not match
[2025-04-09T15:33:15.317+0000] {local_task_job_runner.py:318} WARNING - Recorded pid 29291 does not match the current pid 28633
[2025-04-09T15:33:15.318+0000] {local_task_job_runner.py:218} WARNING - Heartbeat failed with Exception: PID of job runner does not match
[2025-04-09T15:33:20.371+0000] {local_task_job_runner.py:318} WARNING - Recorded pid 29291 does not match the current pid 28633
[2025-04-09T15:33:20.372+0000] {local_task_job_runner.py:218} WARNING - Heartbeat failed with Exception: PID of job runner does not match
[2025-04-09T15:33:25.425+0000] {local_task_job_runner.py:318} WARNING - Recorded pid 29291 does not match the current pid 28633
[2025-04-09T15:33:25.427+0000] {local_task_job_runner.py:218} WARNING - Heartbeat failed with Exception: PID of job runner does not match
[2025-04-09T15:33:30.476+0000] {local_task_job_runner.py:318} WARNING - Recorded pid 29291 does not match the current pid 28633
[2025-04-09T15:33:30.477+0000] {local_task_job_runner.py:218} WARNING - Heartbeat failed with Exception: PID of job runner does not match
[2025-04-09T15:33:35.547+0000] {local_task_job_runner.py:318} WARNING - Recorded pid 29291 does not match the current pid 28633
[2025-04-09T15:33:35.548+0000] {local_task_job_runner.py:218} WARNING - Heartbeat failed with Exception: PID of job runner does not match
[2025-04-09T15:33:40.204+0000] {http.py:145} INFO - Poking: /data/S2.5/weather?q=Portland&APPID=4d13f07efe491003cd53c704f189b00f
[2025-04-09T15:33:40.209+0000] {base.py:84} INFO - Retrieving connection 'weathermap_api'
[2025-04-09T15:33:40.309+0000] {http.py:278} ERROR - HTTP error: Not Found
[2025-04-09T15:33:40.312+0000] {http.py:279} ERROR - {"cod":"404","message":"Internal error"}
[2025-04-09T15:33:40.573+0000] {local_task_job_runner.py:318} WARNING - Recorded pid 29291 does not match the current pid 28633
[2025-04-09T15:33:40.574+0000] {local_task_job_runner.py:218} WARNING - Heartbeat failed with Exception: PID of job runner does not match
[2025-04-09T15:33:45.625+0000] {local_task_job_runner.py:318} WARNING - Recorded pid 29291 does not match the current pid 28633
[2025-04-09T15:33:45.625+0000] {local_task_job_runner.py:218} WARNING - Heartbeat failed with Exception: PID of job runner does not match
[2025-04-09T15:33:50.675+0000] {local_task_job_runner.py:318} WARNING - Recorded pid 29291 does not match the current pid 28633
[2025-04-09T15:33:50.676+0000] {local_task_job_runner.py:218} WARNING - Heartbeat failed with Exception: PID of job runner does not match
[2025-04-09T15:33:55.692+0000] {local_task_job_runner.py:318} WARNING - Recorded pid 29291 does not match the current pid 28633
[2025-04-09T15:33:55.692+0000] {local_task_job_runner.py:218} WARNING - Heartbeat failed with Exception: PID of job runner does not match
[2025-04-09T15:34:00.746+0000] {local_task_job_runner.py:318} WARNING - Recorded pid 29291 does not match the current pid 28633
[2025-04-09T15:34:00.747+0000] {local_task_job_runner.py:218} WARNING - Heartbeat failed with Exception: PID of job runner does not match
[2025-04-09T15:34:05.799+0000] {local_task_job_runner.py:318} WARNING - Recorded pid 29291 does not match the current pid 28633
[2025-04-09T15:34:05.800+0000] {local_task_job_runner.py:218} WARNING - Heartbeat failed with Exception: PID of job runner does not match
[2025-04-09T15:34:10.854+0000] {local_task_job_runner.py:346} WARNING - State of this instance has been externally set to failed. Terminating instance.
[2025-04-09T15:34:10.854+0000] {local_task_job_runner.py:245} INFO - ::endgroup::
[2025-04-09T15:34:10.859+0000] {process_utils.py:132} INFO - Sending 15 to group 28633. PIDs of all processes in the group: [28633]
[2025-04-09T15:34:10.859+0000] {process_utils.py:87} INFO - Sending the signal 15 to group 28633
[2025-04-09T15:34:10.859+0000] {taskinstance.py:3094} ERROR - Received SIGTERM. Terminating subprocesses.
[2025-04-09T15:34:10.863+0000] {taskinstance.py:3095} ERROR - Stacktrace: 
  File "/home/ubuntu/airflow_venv/bin/airflow", line 8, in <module>
    sys.exit(main())
  File "/home/ubuntu/airflow_venv/lib/python3.12/site-packages/airflow/__main__.py", line 62, in main
    args.func(args)
  File "/home/ubuntu/airflow_venv/lib/python3.12/site-packages/airflow/cli/cli_config.py", line 49, in command
    return func(*args, **kwargs)
  File "/home/ubuntu/airflow_venv/lib/python3.12/site-packages/airflow/utils/cli.py", line 116, in wrapper
    return f(*args, **kwargs)
  File "/home/ubuntu/airflow_venv/lib/python3.12/site-packages/airflow/cli/commands/task_command.py", line 483, in task_run
    task_return_code = _run_task_by_selected_method(args, _dag, ti)
  File "/home/ubuntu/airflow_venv/lib/python3.12/site-packages/airflow/cli/commands/task_command.py", line 254, in _run_task_by_selected_method
    return _run_task_by_local_task_job(args, ti)
  File "/home/ubuntu/airflow_venv/lib/python3.12/site-packages/airflow/cli/commands/task_command.py", line 322, in _run_task_by_local_task_job
    ret = run_job(job=job_runner.job, execute_callable=job_runner._execute)
  File "/home/ubuntu/airflow_venv/lib/python3.12/site-packages/airflow/utils/session.py", line 97, in wrapper
    return func(*args, session=session, **kwargs)
  File "/home/ubuntu/airflow_venv/lib/python3.12/site-packages/airflow/jobs/job.py", line 421, in run_job
    return execute_job(job, execute_callable=execute_callable)
  File "/home/ubuntu/airflow_venv/lib/python3.12/site-packages/airflow/jobs/job.py", line 450, in execute_job
    ret = execute_callable()
  File "/home/ubuntu/airflow_venv/lib/python3.12/site-packages/airflow/jobs/local_task_job_runner.py", line 171, in _execute
    self.task_runner.start()
  File "/home/ubuntu/airflow_venv/lib/python3.12/site-packages/airflow/task/task_runner/standard_task_runner.py", line 55, in start
    self.process = self._start_by_fork()
  File "/home/ubuntu/airflow_venv/lib/python3.12/site-packages/airflow/task/task_runner/standard_task_runner.py", line 117, in _start_by_fork
    ret = args.func(args, dag=self.dag)
  File "/home/ubuntu/airflow_venv/lib/python3.12/site-packages/airflow/cli/cli_config.py", line 49, in command
    return func(*args, **kwargs)
  File "/home/ubuntu/airflow_venv/lib/python3.12/site-packages/airflow/utils/cli.py", line 116, in wrapper
    return f(*args, **kwargs)
  File "/home/ubuntu/airflow_venv/lib/python3.12/site-packages/airflow/cli/commands/task_command.py", line 483, in task_run
    task_return_code = _run_task_by_selected_method(args, _dag, ti)
  File "/home/ubuntu/airflow_venv/lib/python3.12/site-packages/airflow/cli/commands/task_command.py", line 256, in _run_task_by_selected_method
    return _run_raw_task(args, ti)
  File "/home/ubuntu/airflow_venv/lib/python3.12/site-packages/airflow/cli/commands/task_command.py", line 341, in _run_raw_task
    return ti._run_raw_task(
  File "/home/ubuntu/airflow_venv/lib/python3.12/site-packages/airflow/utils/session.py", line 97, in wrapper
    return func(*args, session=session, **kwargs)
  File "/home/ubuntu/airflow_venv/lib/python3.12/site-packages/airflow/models/taskinstance.py", line 3006, in _run_raw_task
    return _run_raw_task(
  File "/home/ubuntu/airflow_venv/lib/python3.12/site-packages/airflow/models/taskinstance.py", line 274, in _run_raw_task
    TaskInstance._execute_task_with_callbacks(
  File "/home/ubuntu/airflow_venv/lib/python3.12/site-packages/airflow/models/taskinstance.py", line 3161, in _execute_task_with_callbacks
    result = self._execute_task(context, task_orig)
  File "/home/ubuntu/airflow_venv/lib/python3.12/site-packages/airflow/models/taskinstance.py", line 3185, in _execute_task
    return _execute_task(self, context, task_orig)
  File "/home/ubuntu/airflow_venv/lib/python3.12/site-packages/airflow/models/taskinstance.py", line 768, in _execute_task
    result = _execute_callable(context=context, **execute_callable_kwargs)
  File "/home/ubuntu/airflow_venv/lib/python3.12/site-packages/airflow/models/taskinstance.py", line 734, in _execute_callable
    return ExecutionCallableRunner(
  File "/home/ubuntu/airflow_venv/lib/python3.12/site-packages/airflow/utils/operator_helpers.py", line 252, in run
    return self.func(*args, **kwargs)
  File "/home/ubuntu/airflow_venv/lib/python3.12/site-packages/airflow/models/baseoperator.py", line 424, in wrapper
    return func(self, *args, **kwargs)
  File "/home/ubuntu/airflow_venv/lib/python3.12/site-packages/airflow/providers/http/sensors/http.py", line 169, in execute
    return super().execute(context=context)
  File "/home/ubuntu/airflow_venv/lib/python3.12/site-packages/airflow/models/baseoperator.py", line 424, in wrapper
    return func(self, *args, **kwargs)
  File "/home/ubuntu/airflow_venv/lib/python3.12/site-packages/airflow/sensors/base.py", line 337, in execute
    time.sleep(self._get_next_poke_interval(started_at, run_duration, poke_count))
  File "/home/ubuntu/airflow_venv/lib/python3.12/site-packages/airflow/models/taskinstance.py", line 3095, in signal_handler
    self.log.error("Stacktrace: \n%s", "".join(traceback.format_stack()))

[2025-04-09T15:34:10.902+0000] {taskinstance.py:341} INFO - ::group::Post task execution logs
[2025-04-09T15:34:10.956+0000] {process_utils.py:80} INFO - Process psutil.Process(pid=28633, status='terminated', exitcode=0, started='15:22:38') (28633) terminated with exit code 0
